Workbook

Sheet Data
A1: precip | B1: datetime | C1: monthly total | E1: time | F1: precip | G1: datetime | H1: monthly total | I1: time | J1: precip | K1: datetime | L1: monthly total | M1: time | N1: precip | O1: datetime | P1: monthly total | Q1: time | R1: precip | S1: datetime | T1: monthly total | U1: time | V1: precip | W1: datetime | X1: monthly total | Y1: time | Z1: precip | AA1: datetime | AB1: monthly total | AD1: precip | AE1: datetime | AF1: monthly total | AH1: precip | AI1: datetime | AJ1: monthly total | AL1: precip | AM1: datetime | AN1: monthly total | AP1: precip | AQ1: datetime | AR1: monthly total | AT1: precip | AU1: datetime | AV1: monthly total | AX1: precip | AY1: datetime | AZ1: monthly total | BB1: precip | BC1: datetime | BD1: monthly total | BF1: precip | BG1: datetime | BH1: monthly total | BJ1: precip | BK1: datetime | BL1: monthly total | BN1: precip | BO1: datetime | BP1: monthly total | BR1: precip | BS1: datetime | BT1: monthly total | BV1: precip | BW1: datetime | BX1: monthly total | BZ1: precip | CA1: datetime | CB1: monthly total | CD1: precip | CE1: datetime | CF1: monthly total | CH1: precip | CI1: datetime | CJ1: monthly total | CL1: precip | CM1: datetime | CN1: monthly total | CP1: precip | CQ1: datetime | CR1: monthly total | CT1: precip | CU1: datetime | CV1: monthly total | CX1: precip | CY1: datetime | CZ1: time | DB1: precip | DC1: datetime | DD1: monthly total
A2: =MEDIAN(F2,J2,N2,R2,V2,Z2,AD2,AH2,AL2,AP2,AT2,AX2,BB2,BF2,BJ2,BN2,BR2,BV2,BZ2,CD2,CH2,CL2,CP2,CT2,CX2,DB2) -> 0.85890043 | B2: 46753 | C2: =A2 -> 0.85890043 | E2: 1095744 | F2: 7.8275347 | G2: =E2/24+2 -> 45658 | H2: =F2 -> 7.8275347 | I2: 1086960 | J2: 8.2324781 | K2: =I2/24+2 -> 45292 | L2: =J2 -> 8.2324781 | M2: 1078200 | N2: 0.88990843 | O2: =M2/24+2 -> 44927 | P2: =N2 -> 0.88990843 | Q2: 1069440 | R2: 0 | S2: =Q2/24+2 -> 44562 | T2: =R2 -> 0 | U2: 1060680 | V2: 8.0212297 | W2: =U2/24+2 -> 44197 | X2: =V2 -> 8.0212297 | Y2: 1051896 | Z2: 8.3187628 | AA2: =Y2/24+2 -> 43831 | AB2: =Z2 -> 8.3187628 | AD2: 12.323828 | AE2: 43466 | AF2: =AD2 -> 12.323828 | AH2: 0.81054479 | AI2: 43101 | AJ2: =AH2 -> 0.81054479 | AL2: 3.0118582 | AM2: 42736 | AN2: =AL2 -> 3.0118582 | AP2: 22.216454 | AQ2: 42370 | AR2: =AP2 -> 22.216454 | AT2: 4.5091968 | AU2: 42005 | AV2: =AT2 -> 4.5091968 | AX2: 10.102186 | AY2: 41640 | AZ2: =AX2 -> 10.102186 | BB2: 0.078335345 | BC2: 41275 | BD2: =BB2 -> 0.078335345 | BF2: 0 | BG2: 40909 | BH2: =BF2 -> 0 | BJ2: 11.449639 | BK2: 40544 | BL2: =BJ2 -> 11.449639 | BN2: 1.4335613 | BO2: 40179 | BP2: =BN2 -> 1.4335613 | BR2: 0 | BS2: 39814 | BT2: =BR2 -> 0 | BV2: 0 | BW2: 39448 | BX2: =BV2 -> 0 | BZ2: 0 | CA2: 39083 | CB2: =BZ2 -> 0 | CD2: 0.19652048 | CE2: 38718 | CF2: =CD2 -> 0.19652048 | CH2: 0 | CI2: 38353 | CJ2: =CH2 -> 0 | CL2: 1.8143899 | CM2: 37987 | CN2: =CL2 -> 1.8143899 | CP2: 0 | CQ2: 37622 | CR2: =CP2 -> 0 | CT2: 0 | CU2: 37257 | CV2: =CT2 -> 0 | CX2: 0.19675538 | CY2: 36892 | CZ2: =CX2 -> 0.19675538 | DB2: 0.82789242 | DC2: 36526 | DD2: =DB2 -> 0.82789242
A3: =MEDIAN(F3,J3,N3,R3,V3,Z3,AD3,AH3,AL3,AP3,AT3,AX3,BB3,BF3,BJ3,BN3,BR3,BV3,BZ3,CD3,CH3,CL3,CP3,CT3,CX3,DB3) -> 0.80649778 | B3: 46754 | C3: =IF(MONTH(B3)=MONTH(B2),A3+C2,A3) -> 1.6653982 | E3: 1095768 | F3: 10.797656 | G3: =E3/24+2 -> 45659 | H3: =IF(MONTH(G3)=MONTH(G2),F3+H2,F3) -> 18.625191 | I3: 1086984 | J3: 0 | K3: =I3/24+2 -> 45293 | L3: =IF(MONTH(K3)=MONTH(K2),J3+L2,J3) -> 8.2324781 | M3: 1078224 | N3: 21.935007 | O3: =M3/24+2 -> 44928 | P3: =IF(MONTH(O3)=MONTH(O2),N3+P2,N3) -> 22.824916 | Q3: 1069464 | R3: 0 | S3: =Q3/24+2 -> 44563 | T3: =IF(MONTH(S3)=MONTH(S2),R3+T2,R3) -> 0 | U3: 1060704 | V3: 1.0206215 | W3: =U3/24+2 -> 44198 | X3: =IF(MONTH(W3)=MONTH(W2),V3+X2,V3) -> 9.0418513 | Y3: 1051920 | Z3: 0.064577632 | AA3: =Y3/24+2 -> 43832 | AB3: =IF(MONTH(AA3)=MONTH(AA2),Z3+AB2,Z3) -> 8.3833404 | AD3: 0 | AE3: 43467 | AF3: =IF(MONTH(AE3)=MONTH(AE2),AF2+AD3,AD3) -> 12.323828 | AH3: 12.334131 | AI3: 43102 | AJ3: =IF(MONTH(AI3)=MONTH(AI2),AJ2+AH3,AH3) -> 13.144676 | AL3: 8.0734587 | AM3: 42737 | AN3: =IF(MONTH(AM3)=MONTH(AM2),AN2+AL3,AL3) -> 11.085317 | AP3: 0.10320355 | AQ3: 42371 | AR3: =IF(MONTH(AQ3)=MONTH(AQ2),AR2+AP3,AP3) -> 22.319657 | AT3: 0.76871687 | AU3: 42006 | AV3: =IF(MONTH(AU3)=MONTH(AU2),AV2+AT3,AT3) -> 5.2779136 | AX3: 1.0460055 | AY3: 41641 | AZ3: =IF(MONTH(AY3)=MONTH(AY2),AZ2+AX3,AX3) -> 11.148192 | BB3: 9.6021624 | BC3: 41276 | BD3: =IF(MONTH(BC3)=MONTH(BC2),BD2+BB3,BB3) -> 9.6804977 | BF3: 0.02531814 | BG3: 40910 | BH3: =IF(MONTH(BG3)=MONTH(BG2),BH2+BF3,BF3) -> 0.02531814 | BJ3: 6.5215826 | BK3: 40545 | BL3: =IF(MONTH(BK3)=MONTH(BK2),BL2+BJ3,BJ3) -> 17.971222 | BN3: 0 | BO3: 40180 | BP3: =IF(MONTH(BO3)=MONTH(BO2),BP2+BN3,BN3) -> 1.4335613 | BR3: 2.9692864 | BS3: 39815 | BT3: =IF(MONTH(BS3)=MONTH(BS2),BT2+BR3,BR3) -> 2.9692864 | BV3: 11.011889 | BW3: 39449 | BX3: =IF(MONTH(BW3)=MONTH(BW2),BX2+BV3,BV3) -> 11.011889 | BZ3: 0 | CA3: 39084 | CB3: =IF(MONTH(CA3)=MONTH(CA2),CB2+BZ3,BZ3) -> 0 | CD3: 0.022238014 | CE3: 38719 | CF3: =IF(MONTH(CE3)=MONTH(CE2),CF2+CD3,CD3) -> 0.21875849 | CH3: 0 | CI3: 38354 | CJ3: =IF(MONTH(CI3)=MONTH(CI2),CJ2+CH3,CH3) -> 0 | CL3: 3.8439841 | CM3: 37988 | CN3: =IF(MONTH(CM3)=MONTH(CM2),CN2+CL3,CL3) -> 5.6583741 | CP3: 1.4156288 | CQ3: 37623 | CR3: =IF(MONTH(CQ3)=MONTH(CQ2),CR2+CP3,CP3) -> 1.4156288 | CT3: 0.84427869 | CU3: 37258 | CV3: =IF(MONTH(CU3)=MONTH(CU2),CV2+CT3,CT3) -> 0.84427869 | CX3: 0 | CY3: 36893 | CZ3: =IF(MONTH(CY3)=MONTH(CY2),CZ2+CX3,CX3) -> 0.19675538 | DB3: 0.052262794 | DC3: 36527 | DD3: =IF(MONTH(DC3)=MONTH(DC2),DD2+DB3,DB3) -> 0.88015522
A4: =MEDIAN(F4,J4,N4,R4,V4,Z4,AD4,AH4,AL4,AP4,AT4,AX4,BB4,BF4,BJ4,BN4,BR4,BV4,BZ4,CD4,CH4,CL4,CP4,CT4,CX4,DB4) -> 2.2563266 | B4: 46755 | C4: =IF(MONTH(B4)=MONTH(B3),A4+C3,A4) -> 3.9217248 | E4: 1095792 | F4: 27.593414 | G4: =E4/24+2 -> 45660 | H4: =IF(MONTH(G4)=MONTH(G3),F4+H3,F4) -> 46.218605 | I4: 1087008 | J4: 0 | K4: =I4/24+2 -> 45294 | L4: =IF(MONTH(K4)=MONTH(K3),J4+L3,J4) -> 8.2324781 | M4: 1078248 | N4: 7.8607583 | O4: =M4/24+2 -> 44929 | P4: =IF(MONTH(O4)=MONTH(O3),N4+P3,N4) -> 30.685674 | Q4: 1069488 | R4: 0.91110086 | S4: =Q4/24+2 -> 44564 | T4: =IF(MONTH(S4)=MONTH(S3),R4+T3,R4) -> 0.91110086 | U4: 1060728 | V4: 4.2330947 | W4: =U4/24+2 -> 44199 | X4: =IF(MONTH(W4)=MONTH(W3),V4+X3,V4) -> 13.274946 | Y4: 1051944 | Z4: 3.318222 | AA4: =Y4/24+2 -> 43833 | AB4: =IF(MONTH(AA4)=MONTH(AA3),Z4+AB3,Z4) -> 11.701562 | AD4: 0 | AE4: 43468 | AF4: =IF(MONTH(AE4)=MONTH(AE3),AF3+AD4,AD4) -> 12.323828 | AH4: 0 | AI4: 43103 | AJ4: =IF(MONTH(AI4)=MONTH(AI3),AJ3+AH4,AH4) -> 13.144676 | AL4: 7.2609682 | AM4: 42738 | AN4: =IF(MONTH(AM4)=MONTH(AM3),AN3+AL4,AL4) -> 18.346285 | AP4: 1.1888789 | AQ4: 42372 | AR4: =IF(MONTH(AQ4)=MONTH(AQ3),AR3+AP4,AP4) -> 23.508536 | AT4: 0.21596649 | AU4: 42007 | AV4: =IF(MONTH(AU4)=MONTH(AU3),AV3+AT4,AT4) -> 5.4938801 | AX4: 3.4153252 | AY4: 41642 | AZ4: =IF(MONTH(AY4)=MONTH(AY3),AZ3+AX4,AX4) -> 14.563517 | BB4: 4.0283427 | BC4: 41277 | BD4: =IF(MONTH(BC4)=MONTH(BC3),BD3+BB4,BB4) -> 13.70884 | BF4: 9.9416752 | BG4: 40911 | BH4: =IF(MONTH(BG4)=MONTH(BG3),BH3+BF4,BF4) -> 9.9669933 | BJ4: 9.8392591 | BK4: 40546 | BL4: =IF(MONTH(BK4)=MONTH(BK3),BL3+BJ4,BJ4) -> 27.810481 | BN4: 0 | BO4: 40181 | BP4: =IF(MONTH(BO4)=MONTH(BO3),BP3+BN4,BN4) -> 1.4335613 | BR4: 4.3797708 | BS4: 39816 | BT4: =IF(MONTH(BS4)=MONTH(BS3),BT3+BR4,BR4) -> 7.3490572 | BV4: 0 | BW4: 39450 | BX4: =IF(MONTH(BW4)=MONTH(BW3),BX3+BV4,BV4) -> 11.011889 | BZ4: 0.29056293 | CA4: 39085 | CB4: =IF(MONTH(CA4)=MONTH(CA3),CB3+BZ4,BZ4) -> 0.29056293 | CD4: 3.6232727 | CE4: 38720 | CF4: =IF(MONTH(CE4)=MONTH(CE3),CF3+CD4,CD4) -> 3.8420311 | CH4: 0.14685497 | CI4: 38355 | CJ4: =IF(MONTH(CI4)=MONTH(CI3),CJ3+CH4,CH4) -> 0.14685497 | CL4: 7.1580215 | CM4: 37989 | CN4: =IF(MONTH(CM4)=MONTH(CM3),CN3+CL4,CL4) -> 12.816396 | CP4: 0.89132386 | CQ4: 37624 | CR4: =IF(MONTH(CQ4)=MONTH(CQ3),CR3+CP4,CP4) -> 2.3069527 | CT4: 2.3720319 | CU4: 37259 | CV4: =IF(MONTH(CU4)=MONTH(CU3),CV3+CT4,CT4) -> 3.2163106 | CX4: 0.046943285 | CY4: 36894 | CZ4: =IF(MONTH(CY4)=MONTH(CY3),CZ3+CX4,CX4) -> 0.24369866 | DB4: 2.1406212 | DC4: 36528 | DD4: =IF(MONTH(DC4)=MONTH(DC3),DD3+DB4,DB4) -> 3.0207764
A5: =MEDIAN(F5,J5,N5,R5,V5,Z5,AD5,AH5,AL5,AP5,AT5,AX5,BB5,BF5,BJ5,BN5,BR5,BV5,BZ5,CD5,CH5,CL5,CP5,CT5,CX5,DB5) -> 0.66743878 | B5: 46756 | C5: =IF(MONTH(B5)=MONTH(B4),A5+C4,A5) -> 4.5891635 | E5: 1095816 | F5: 10.383561 | G5: =E5/24+2 -> 45661 | H5: =IF(MONTH(G5)=MONTH(G4),F5+H4,F5) -> 56.602166 | I5: 1087032 | J5: 1.7429186 | K5: =I5/24+2 -> 45295 | L5: =IF(MONTH(K5)=MONTH(K4),J5+L4,J5) -> 9.9753968 | M5: 1078272 | N5: 2.0237236 | O5: =M5/24+2 -> 44930 | P5: =IF(MONTH(O5)=MONTH(O4),N5+P4,N5) -> 32.709397 | Q5: 1069512 | R5: 0 | S5: =Q5/24+2 -> 44565 | T5: =IF(MONTH(S5)=MONTH(S4),R5+T4,R5) -> 0.91110086 | U5: 1060752 | V5: 9.4825468 | W5: =U5/24+2 -> 44200 | X5: =IF(MONTH(W5)=MONTH(W4),V5+X4,V5) -> 22.757493 | Y5: 1051968 | Z5: 0.77788323 | AA5: =Y5/24+2 -> 43834 | AB5: =IF(MONTH(AA5)=MONTH(AA4),Z5+AB4,Z5) -> 12.479446 | AD5: 0.2391393 | AE5: 43469 | AF5: =IF(MONTH(AE5)=MONTH(AE4),AF4+AD5,AD5) -> 12.562967 | AH5: 0.12848644 | AI5: 43104 | AJ5: =IF(MONTH(AI5)=MONTH(AI4),AJ4+AH5,AH5) -> 13.273162 | AL5: 0 | AM5: 42739 | AN5: =IF(MONTH(AM5)=MONTH(AM4),AN4+AL5,AL5) -> 18.346285 | AP5: 0 | AQ5: 42373 | AR5: =IF(MONTH(AQ5)=MONTH(AQ4),AR4+AP5,AP5) -> 23.508536 | AT5: 29.055313 | AU5: 42008 | AV5: =IF(MONTH(AU5)=MONTH(AU4),AV4+AT5,AT5) -> 34.549193 | AX5: 2.9104409 | AY5: 41643 | AZ5: =IF(MONTH(AY5)=MONTH(AY4),AZ4+AX5,AX5) -> 17.473958 | BB5: 24.905481 | BC5: 41278 | BD5: =IF(MONTH(BC5)=MONTH(BC4),BD4+BB5,BB5) -> 38.614322 | BF5: 5.4669189 | BG5: 40912 | BH5: =IF(MONTH(BG5)=MONTH(BG4),BH4+BF5,BF5) -> 15.433912 | BJ5: 1.7321556 | BK5: 40547 | BL5: =IF(MONTH(BK5)=MONTH(BK4),BL4+BJ5,BJ5) -> 29.542637 | BN5: 0 | BO5: 40182 | BP5: =IF(MONTH(BO5)=MONTH(BO4),BP4+BN5,BN5) -> 1.4335613 | BR5: 0.14601777 | BS5: 39817 | BT5: =IF(MONTH(BS5)=MONTH(BS4),BT4+BR5,BR5) -> 7.495075 | BV5: 0.7875796 | BW5: 39451 | BX5: =IF(MONTH(BW5)=MONTH(BW4),BX4+BV5,BV5) -> 11.799469 | BZ5: 0.072654039 | CA5: 39086 | CB5: =IF(MONTH(CA5)=MONTH(CA4),CB4+BZ5,BZ5) -> 0.36321697 | CD5: 0 | CE5: 38721 | CF5: =IF(MONTH(CE5)=MONTH(CE4),CF4+CD5,CD5) -> 3.8420311 | CH5: 0.29263121 | CI5: 38356 | CJ5: =IF(MONTH(CI5)=MONTH(CI4),CJ4+CH5,CH5) -> 0.43948618 | CL5: 9.5311728 | CM5: 37990 | CN5: =IF(MONTH(CM5)=MONTH(CM4),CN4+CL5,CL5) -> 22.347568 | CP5: 0.20926563 | CQ5: 37625 | CR5: =IF(MONTH(CQ5)=MONTH(CQ4),CR4+CP5,CP5) -> 2.5162183 | CT5: 0.55699432 | CU5: 37260 | CV5: =IF(MONTH(CU5)=MONTH(CU4),CV4+CT5,CT5) -> 3.7733049 | CX5: 0 | CY5: 36895 | CZ5: =IF(MONTH(CY5)=MONTH(CY4),CZ4+CX5,CX5) -> 0.24369866 | DB5: 2.2681172 | DC5: 36529 | DD5: =IF(MONTH(DC5)=MONTH(DC4),DD4+DB5,DB5) -> 5.2888936
A6: =MEDIAN(F6,J6,N6,R6,V6,Z6,AD6,AH6,AL6,AP6,AT6,AX6,BB6,BF6,BJ6,BN6,BR6,BV6,BZ6,CD6,CH6,CL6,CP6,CT6,CX6,DB6) -> 2.002196 | B6: 46757 | C6: =IF(MONTH(B6)=MONTH(B5),A6+C5,A6) -> 6.5913596 | E6: 1095840 | F6: 13.178088 | G6: =E6/24+2 -> 45662 | H6: =IF(MONTH(G6)=MONTH(G5),F6+H5,F6) -> 69.780254 | I6: 1087056 | J6: 1.4649743 | K6: =I6/24+2 -> 45296 | L6: =IF(MONTH(K6)=MONTH(K5),J6+L5,J6) -> 11.440371 | M6: 1078296 | N6: 3.8878548 | O6: =M6/24+2 -> 44931 | P6: =IF(MONTH(O6)=MONTH(O5),N6+P5,N6) -> 36.597252 | Q6: 1069536 | R6: 1.6972231 | S6: =Q6/24+2 -> 44566 | T6: =IF(MONTH(S6)=MONTH(S5),R6+T5,R6) -> 2.6083239 | U6: 1060776 | V6: 23.10561 | W6: =U6/24+2 -> 44201 | X6: =IF(MONTH(W6)=MONTH(W5),V6+X5,V6) -> 45.863103 | Y6: 1051992 | Z6: 0 | AA6: =Y6/24+2 -> 43835 | AB6: =IF(MONTH(AA6)=MONTH(AA5),Z6+AB5,Z6) -> 12.479446 | AD6: 3.8549747 | AE6: 43470 | AF6: =IF(MONTH(AE6)=MONTH(AE5),AF5+AD6,AD6) -> 16.417942 | AH6: 24.132992 | AI6: 43105 | AJ6: =IF(MONTH(AI6)=MONTH(AI5),AJ5+AH6,AH6) -> 37.406154 | AL6: 5.9922919 | AM6: 42740 | AN6: =IF(MONTH(AM6)=MONTH(AM5),AN5+AL6,AL6) -> 24.338577 | AP6: 1.5413231 | AQ6: 42374 | AR6: =IF(MONTH(AQ6)=MONTH(AQ5),AR5+AP6,AP6) -> 25.049859 | AT6: 1.4448609 | AU6: 42009 | AV6: =IF(MONTH(AU6)=MONTH(AU5),AV5+AT6,AT6) -> 35.994054 | AX6: 16.984205 | AY6: 41644 | AZ6: =IF(MONTH(AY6)=MONTH(AY5),AZ5+AX6,AX6) -> 34.458163 | BB6: 16.011612 | BC6: 41279 | BD6: =IF(MONTH(BC6)=MONTH(BC5),BD5+BB6,BB6) -> 54.625934 | BF6: 2.1198814 | BG6: 40913 | BH6: =IF(MONTH(BG6)=MONTH(BG5),BH5+BF6,BF6) -> 17.553794 | BJ6: 2.7765746 | BK6: 40548 | BL6: =IF(MONTH(BK6)=MONTH(BK5),BL5+BJ6,BJ6) -> 32.319211 | BN6: 0 | BO6: 40183 | BP6: =IF(MONTH(BO6)=MONTH(BO5),BP5+BN6,BN6) -> 1.4335613 | BR6: 0.21914801 | BS6: 39818 | BT6: =IF(MONTH(BS6)=MONTH(BS5),BT5+BR6,BR6) -> 7.714223 | BV6: 12.73663 | BW6: 39452 | BX6: =IF(MONTH(BW6)=MONTH(BW5),BX5+BV6,BV6) -> 24.536099 | BZ6: 0 | CA6: 39087 | CB6: =IF(MONTH(CA6)=MONTH(CA5),CB5+BZ6,BZ6) -> 0.36321697 | CD6: 0.77195895 | CE6: 38722 | CF6: =IF(MONTH(CE6)=MONTH(CE5),CF5+CD6,CD6) -> 4.6139901 | CH6: 3.5103383 | CI6: 38357 | CJ6: =IF(MONTH(CI6)=MONTH(CI5),CJ5+CH6,CH6) -> 3.9498245 | CL6: 0.75845355 | CM6: 37991 | CN6: =IF(MONTH(CM6)=MONTH(CM5),CN5+CL6,CL6) -> 23.106022 | CP6: 20.16176 | CQ6: 37626 | CR6: =IF(MONTH(CQ6)=MONTH(CQ5),CR5+CP6,CP6) -> 22.677979 | CT6: 0.061880894 | CU6: 37261 | CV6: =IF(MONTH(CU6)=MONTH(CU5),CV5+CT6,CT6) -> 3.8351858 | CX6: 1.8845106 | CY6: 36896 | CZ6: =IF(MONTH(CY6)=MONTH(CY5),CZ5+CX6,CX6) -> 2.1282093 | DB6: 1.4771733 | DC6: 36530 | DD6: =IF(MONTH(DC6)=MONTH(DC5),DD5+DB6,DB6) -> 6.7660669
A7: =MEDIAN(F7,J7,N7,R7,V7,Z7,AD7,AH7,AL7,AP7,AT7,AX7,BB7,BF7,BJ7,BN7,BR7,BV7,BZ7,CD7,CH7,CL7,CP7,CT7,CX7,DB7) -> 5.2176955 | B7: 46758 | C7: =IF(MONTH(B7)=MONTH(B6),A7+C6,A7) -> 11.809055 | E7: 1095864 | F7: 9.5829906 | G7: =E7/24+2 -> 45663 | H7: =IF(MONTH(G7)=MONTH(G6),F7+H6,F7) -> 79.363245 | I7: 1087080 | J7: 3.9207828 | K7: =I7/24+2 -> 45297 | L7: =IF(MONTH(K7)=MONTH(K6),J7+L6,J7) -> 15.361154 | M7: 1078320 | N7: 2.0893412 | O7: =M7/24+2 -> 44932 | P7: =IF(MONTH(O7)=MONTH(O6),N7+P6,N7) -> 38.686593 | Q7: 1069560 | R7: 0.54049706 | S7: =Q7/24+2 -> 44567 | T7: =IF(MONTH(S7)=MONTH(S6),R7+T6,R7) -> 3.148821 | U7: 1060800 | V7: 10.966619 | W7: =U7/24+2 -> 44202 | X7: =IF(MONTH(W7)=MONTH(W6),V7+X6,V7) -> 56.829721 | Y7: 1052016 | Z7: 0 | AA7: =Y7/24+2 -> 43836 | AB7: =IF(MONTH(AA7)=MONTH(AA6),Z7+AB6,Z7) -> 12.479446 | AD7: 1.9594729 | AE7: 43471 | AF7: =IF(MONTH(AE7)=MONTH(AE6),AF6+AD7,AD7) -> 18.377415 | AH7: 20.952921 | AI7: 43106 | AJ7: =IF(MONTH(AI7)=MONTH(AI6),AJ6+AH7,AH7) -> 58.359075 | AL7: 76.432457 | AM7: 42741 | AN7: =IF(MONTH(AM7)=MONTH(AM6),AN6+AL7,AL7) -> 100.77103 | AP7: 31.041681 | AQ7: 42375 | AR7: =IF(MONTH(AQ7)=MONTH(AQ6),AR6+AP7,AP7) -> 56.09154 | AT7: 4.674624 | AU7: 42010 | AV7: =IF(MONTH(AU7)=MONTH(AU6),AV6+AT7,AT7) -> 40.668678 | AX7: 24.241604 | AY7: 41645 | AZ7: =IF(MONTH(AY7)=MONTH(AY6),AZ6+AX7,AX7) -> 58.699767 | BB7: 9.2432556 | BC7: 41280 | BD7: =IF(MONTH(BC7)=MONTH(BC6),BD6+BB7,BB7) -> 63.869189 | BF7: 14.732018 | BG7: 40914 | BH7: =IF(MONTH(BG7)=MONTH(BG6),BH6+BF7,BF7) -> 32.285811 | BJ7: 34.648594 | BK7: 40549 | BL7: =IF(MONTH(BK7)=MONTH(BK6),BL6+BJ7,BJ7) -> 66.967805 | BN7: 0 | BO7: 40184 | BP7: =IF(MONTH(BO7)=MONTH(BO6),BP6+BN7,BN7) -> 1.4335613 | BR7: 4.4603477 | BS7: 39819 | BT7: =IF(MONTH(BS7)=MONTH(BS6),BT6+BR7,BR7) -> 12.174571 | BV7: 81.424423 | BW7: 39453 | BX7: =IF(MONTH(BW7)=MONTH(BW6),BX6+BV7,BV7) -> 105.96052 | BZ7: 0 | CA7: 39088 | CB7: =IF(MONTH(CA7)=MONTH(CA6),CB6+BZ7,BZ7) -> 0.36321697 | CD7: 0.51298046 | CE7: 38723 | CF7: =IF(MONTH(CE7)=MONTH(CE6),CF6+CD7,CD7) -> 5.1269706 | CH7: 0.69685858 | CI7: 38358 | CJ7: =IF(MONTH(CI7)=MONTH(CI6),CJ6+CH7,CH7) -> 4.6466831 | CL7: 5.760767 | CM7: 37992 | CN7: =IF(MONTH(CM7)=MONTH(CM6),CN6+CL7,CL7) -> 28.866789 | CP7: 3.9406948 | CQ7: 37627 | CR7: =IF(MONTH(CQ7)=MONTH(CQ6),CR6+CP7,CP7) -> 26.618673 | CT7: 19.471958 | CU7: 37262 | CV7: =IF(MONTH(CU7)=MONTH(CU6),CV6+CT7,CT7) -> 23.307144 | CX7: 0 | CY7: 36897 | CZ7: =IF(MONTH(CY7)=MONTH(CY6),CZ6+CX7,CX7) -> 2.1282093 | DB7: 10.912002 | DC7: 36531 | DD7: =IF(MONTH(DC7)=MONTH(DC6),DD6+DB7,DB7) -> 17.678069
A8: =MEDIAN(F8,J8,N8,R8,V8,Z8,AD8,AH8,AL8,AP8,AT8,AX8,BB8,BF8,BJ8,BN8,BR8,BV8,BZ8,CD8,CH8,CL8,CP8,CT8,CX8,DB8) -> 1.8387128 | B8: 46759 | C8: =IF(MONTH(B8)=MONTH(B7),A8+C7,A8) -> 13.647768 | E8: 1095888 | F8: 2.6603875 | G8: =E8/24+2 -> 45664 | H8: =IF(MONTH(G8)=MONTH(G7),F8+H7,F8) -> 82.023633 | I8: 1087104 | J8: 0.25336656 | K8: =I8/24+2 -> 45298 | L8: =IF(MONTH(K8)=MONTH(K7),J8+L7,J8) -> 15.61452 | M8: 1078344 | N8: 55.914516 | O8: =M8/24+2 -> 44933 | P8: =IF(MONTH(O8)=MONTH(O7),N8+P7,N8) -> 94.60111 | Q8: 1069584 | R8: 0 | S8: =Q8/24+2 -> 44568 | T8: =IF(MONTH(S8)=MONTH(S7),R8+T7,R8) -> 3.148821 | U8: 1060824 | V8: 1.017038 | W8: =U8/24+2 -> 44203 | X8: =IF(MONTH(W8)=MONTH(W7),V8+X7,V8) -> 57.846759 | Y8: 1052040 | Z8: 0 | AA8: =Y8/24+2 -> 43837 | AB8: =IF(MONTH(AA8)=MONTH(AA7),Z8+AB7,Z8) -> 12.479446 | AD8: 0.17995551 | AE8: 43472 | AF8: =IF(MONTH(AE8)=MONTH(AE7),AF7+AD8,AD8) -> 18.55737 | AH8: 4.1250949 | AI8: 43107 | AJ8: =IF(MONTH(AI8)=MONTH(AI7),AJ7+AH8,AH8) -> 62.48417 | AL8: 28.852676 | AM8: 42742 | AN8: =IF(MONTH(AM8)=MONTH(AM7),AN7+AL8,AL8) -> 129.62371 | AP8: 64.795738 | AQ8: 42376 | AR8: =IF(MONTH(AQ8)=MONTH(AQ7),AR7+AP8,AP8) -> 120.88728 | AT8: 0.38879251 | AU8: 42011 | AV8: =IF(MONTH(AU8)=MONTH(AU7),AV7+AT8,AT8) -> 41.057471 | AX8: 7.7220716 | AY8: 41646 | AZ8: =IF(MONTH(AY8)=MONTH(AY7),AZ7+AX8,AX8) -> 66.421839 | BB8: 0.89729577 | BC8: 41281 | BD8: =IF(MONTH(BC8)=MONTH(BC7),BD7+BB8,BB8) -> 64.766485 | BF8: 13.858957 | BG8: 40915 | BH8: =IF(MONTH(BG8)=MONTH(BG7),BH7+BF8,BF8) -> 46.144768 | BJ8: 3.2260692 | BK8: 40550 | BL8: =IF(MONTH(BK8)=MONTH(BK7),BL7+BJ8,BJ8) -> 70.193874 | BN8: 0 | BO8: 40185 | BP8: =IF(MONTH(BO8)=MONTH(BO7),BP7+BN8,BN8) -> 1.4335613 | BR8: 2.9240041 | BS8: 39820 | BT8: =IF(MONTH(BS8)=MONTH(BS7),BT7+BR8,BR8) -> 15.098575 | BV8: 11.719097 | BW8: 39454 | BX8: =IF(MONTH(BW8)=MONTH(BW7),BX7+BV8,BV8) -> 117.67962 | BZ8: 0 | CA8: 39089 | CB8: =IF(MONTH(CA8)=MONTH(CA7),CB7+BZ8,BZ8) -> 0.36321697 | CD8: 0.51572144 | CE8: 38724 | CF8: =IF(MONTH(CE8)=MONTH(CE7),CF7+CD8,CD8) -> 5.642692 | CH8: 0.61266971 | CI8: 38359 | CJ8: =IF(MONTH(CI8)=MONTH(CI7),CJ7+CH8,CH8) -> 5.2593528 | CL8: 8.8423681 | CM8: 37993 | CN8: =IF(MONTH(CM8)=MONTH(CM7),CN7+CL8,CL8) -> 37.709157 | CP8: 0.28301549 | CQ8: 37628 | CR8: =IF(MONTH(CQ8)=MONTH(CQ7),CR7+CP8,CP8) -> 26.901689 | CT8: 3.3544743 | CU8: 37263 | CV8: =IF(MONTH(CU8)=MONTH(CU7),CV7+CT8,CT8) -> 26.661618 | CX8: 0.021598525 | CY8: 36898 | CZ8: =IF(MONTH(CY8)=MONTH(CY7),CZ7+CX8,CX8) -> 2.1498078 | DB8: 8.6422253 | DC8: 36532 | DD8: =IF(MONTH(DC8)=MONTH(DC7),DD7+DB8,DB8) -> 26.320294
A9: =MEDIAN(F9,J9,N9,R9,V9,Z9,AD9,AH9,AL9,AP9,AT9,AX9,BB9,BF9,BJ9,BN9,BR9,BV9,BZ9,CD9,CH9,CL9,CP9,CT9,CX9,DB9) -> 1.2133296 | B9: 46760 | C9: =IF(MONTH(B9)=MONTH(B8),A9+C8,A9) -> 14.861097 | E9: 1095912 | F9: 23.211172 | G9: =E9/24+2 -> 45665 | H9: =IF(MONTH(G9)=MONTH(G8),F9+H8,F9) -> 105.2348 | I9: 1087128 | J9: 0 | K9: =I9/24+2 -> 45299 | L9: =IF(MONTH(K9)=MONTH(K8),J9+L8,J9) -> 15.61452 | M9: 1078368 | N9: 1.2332082 | O9: =M9/24+2 -> 44934 | P9: =IF(MONTH(O9)=MONTH(O8),N9+P8,N9) -> 95.834318 | Q9: 1069608 | R9: 0 | S9: =Q9/24+2 -> 44569 | T9: =IF(MONTH(S9)=MONTH(S8),R9+T8,R9) -> 3.148821 | U9: 1060848 | V9: 1.1879305 | W9: =U9/24+2 -> 44204 | X9: =IF(MONTH(W9)=MONTH(W8),V9+X8,V9) -> 59.03469 | Y9: 1052064 | Z9: 0 | AA9: =Y9/24+2 -> 43838 | AB9: =IF(MONTH(AA9)=MONTH(AA8),Z9+AB8,Z9) -> 12.479446 | AD9: 11.483086 | AE9: 43473 | AF9: =IF(MONTH(AE9)=MONTH(AE8),AF8+AD9,AD9) -> 30.040456 | AH9: 11.626712 | AI9: 43108 | AJ9: =IF(MONTH(AI9)=MONTH(AI8),AJ8+AH9,AH9) -> 74.110882 | AL9: 21.745293 | AM9: 42743 | AN9: =IF(MONTH(AM9)=MONTH(AM8),AN8+AL9,AL9) -> 151.369 | AP9: 1.1225173 | AQ9: 42377 | AR9: =IF(MONTH(AQ9)=MONTH(AQ8),AR8+AP9,AP9) -> 122.0098 | AT9: 0 | AU9: 42012 | AV9: =IF(MONTH(AU9)=MONTH(AU8),AV8+AT9,AT9) -> 41.057471 | AX9: 7.7584138 | AY9: 41647 | AZ9: =IF(MONTH(AY9)=MONTH(AY8),AZ8+AX9,AX9) -> 74.180252 | BB9: 0.17767683 | BC9: 41282 | BD9: =IF(MONTH(BC9)=MONTH(BC8),BD8+BB9,BB9) -> 64.944162 | BF9: 21.287455 | BG9: 40916 | BH9: =IF(MONTH(BG9)=MONTH(BG8),BH8+BF9,BF9) -> 67.432223 | BJ9: 19.456032 | BK9: 40551 | BL9: =IF(MONTH(BK9)=MONTH(BK8),BL8+BJ9,BJ9) -> 89.649906 | BN9: 0.72683203 | BO9: 40186 | BP9: =IF(MONTH(BO9)=MONTH(BO8),BP8+BN9,BN9) -> 2.1603934 | BR9: 3.963784 | BS9: 39821 | BT9: =IF(MONTH(BS9)=MONTH(BS8),BT8+BR9,BR9) -> 19.062359 | BV9: 12.635552 | BW9: 39455 | BX9: =IF(MONTH(BW9)=MONTH(BW8),BX8+BV9,BV9) -> 130.31517 | BZ9: 0 | CA9: 39090 | CB9: =IF(MONTH(CA9)=MONTH(CA8),CB8+BZ9,BZ9) -> 0.36321697 | CD9: 3.8748925 | CE9: 38725 | CF9: =IF(MONTH(CE9)=MONTH(CE8),CF8+CD9,CD9) -> 9.5175845 | CH9: 0.29576129 | CI9: 38360 | CJ9: =IF(MONTH(CI9)=MONTH(CI8),CJ8+CH9,CH9) -> 5.5551141 | CL9: 1.193451 | CM9: 37994 | CN9: =IF(MONTH(CM9)=MONTH(CM8),CN8+CL9,CL9) -> 38.902608 | CP9: 0 | CQ9: 37629 | CR9: =IF(MONTH(CQ9)=MONTH(CQ8),CR8+CP9,CP9) -> 26.901689 | CT9: 5.0336399 | CU9: 37264 | CV9: =IF(MONTH(CU9)=MONTH(CU8),CV8+CT9,CT9) -> 31.695258 | CX9: 0.020147445 | CY9: 36899 | CZ9: =IF(MONTH(CY9)=MONTH(CY8),CZ8+CX9,CX9) -> 2.1699553 | DB9: 2.6009479 | DC9: 36533 | DD9: =IF(MONTH(DC9)=MONTH(DC8),DD8+DB9,DB9) -> 28.921242
A10: =MEDIAN(F10,J10,N10,R10,V10,Z10,AD10,AH10,AL10,AP10,AT10,AX10,BB10,BF10,BJ10,BN10,BR10,BV10,BZ10,CD10,CH10,CL10,CP10,CT10,CX10,DB10) -> 2.5103755 | B10: 46761 | C10: =IF(MONTH(B10)=MONTH(B9),A10+C9,A10) -> 17.371473 | E10: 1095936 | F10: 1.8291565 | G10: =E10/24+2 -> 45666 | H10: =IF(MONTH(G10)=MONTH(G9),F10+H9,F10) -> 107.06396 | I10: 1087152 | J10: 19.24441 | K10: =I10/24+2 -> 45300 | L10: =IF(MONTH(K10)=MONTH(K9),J10+L9,J10) -> 34.85893 | M10: 1078392 | N10: 7.3922853 | O10: =M10/24+2 -> 44935 | P10: =IF(MONTH(O10)=MONTH(O9),N10+P9,N10) -> 103.2266 | Q10: 1069632 | R10: 0 | S10: =Q10/24+2 -> 44570 | T10: =IF(MONTH(S10)=MONTH(S9),R10+T9,R10) -> 3.148821 | U10: 1060872 | V10: 3.304688 | W10: =U10/24+2 -> 44205 | X10: =IF(MONTH(W10)=MONTH(W9),V10+X9,V10) -> 62.339378 | Y10: 1052088 | Z10: 0 | AA10: =Y10/24+2 -> 43839 | AB10: =IF(MONTH(AA10)=MONTH(AA9),Z10+AB9,Z10) -> 12.479446 | AD10: 39.933109 | AE10: 43474 | AF10: =IF(MONTH(AE10)=MONTH(AE9),AF9+AD10,AD10) -> 69.973565 | AH10: 7.5695009 | AI10: 43109 | AJ10: =IF(MONTH(AI10)=MONTH(AI9),AJ9+AH10,AH10) -> 81.680383 | AL10: 1.0164187 | AM10: 42744 | AN10: =IF(MONTH(AM10)=MONTH(AM9),AN9+AL10,AL10) -> 152.38542 | AP10: 0.42890072 | AQ10: 42378 | AR10: =IF(MONTH(AQ10)=MONTH(AQ9),AR9+AP10,AP10) -> 122.4387 | AT10: 10.081379 | AU10: 42013 | AV10: =IF(MONTH(AU10)=MONTH(AU9),AV9+AT10,AT10) -> 51.13885 | AX10: 25.026781 | AY10: 41648 | AZ10: =IF(MONTH(AY10)=MONTH(AY9),AZ9+AX10,AX10) -> 99.207033 | BB10: 0 | BC10: 41283 | BD10: =IF(MONTH(BC10)=MONTH(BC9),BD9+BB10,BB10) -> 64.944162 | BF10: 8.5462408 | BG10: 40917 | BH10: =IF(MONTH(BG10)=MONTH(BG9),BH9+BF10,BF10) -> 75.978464 | BJ10: 27.830692 | BK10: 40552 | BL10: =IF(MONTH(BK10)=MONTH(BK9),BL9+BJ10,BJ10) -> 117.4806 | BN10: 2.9088757 | BO10: 40187 | BP10: =IF(MONTH(BO10)=MONTH(BO9),BP9+BN10,BN10) -> 5.0692691 | BR10: 2.9973352 | BS10: 39822 | BT10: =IF(MONTH(BS10)=MONTH(BS9),BT9+BR10,BR10) -> 22.059694 | BV10: 0.37965795 | BW10: 39456 | BX10: =IF(MONTH(BW10)=MONTH(BW9),BX9+BV10,BV10) -> 130.69483 | BZ10: 0 | CA10: 39091 | CB10: =IF(MONTH(CA10)=MONTH(CA9),CB9+BZ10,BZ10) -> 0.36321697 | CD10: 2.485146 | CE10: 38726 | CF10: =IF(MONTH(CE10)=MONTH(CE9),CF9+CD10,CD10) -> 12.002731 | CH10: 0.31669971 | CI10: 38361 | CJ10: =IF(MONTH(CI10)=MONTH(CI9),CJ9+CH10,CH10) -> 5.8718138 | CL10: 2.535605 | CM10: 37995 | CN10: =IF(MONTH(CM10)=MONTH(CM9),CN9+CL10,CL10) -> 41.438213 | CP10: 5.7124295 | CQ10: 37630 | CR10: =IF(MONTH(CQ10)=MONTH(CQ9),CR9+CP10,CP10) -> 32.614118 | CT10: 1.1902454 | CU10: 37265 | CV10: =IF(MONTH(CU10)=MONTH(CU9),CV9+CT10,CT10) -> 32.885504 | CX10: 0 | CY10: 36900 | CZ10: =IF(MONTH(CY10)=MONTH(CY9),CZ9+CX10,CX10) -> 2.1699553 | DB10: 2.0554938 | DC10: 36534 | DD10: =IF(MONTH(DC10)=MONTH(DC9),DD9+DB10,DB10) -> 30.976735
A11: =MEDIAN(F11,J11,N11,R11,V11,Z11,AD11,AH11,AL11,AP11,AT11,AX11,BB11,BF11,BJ11,BN11,BR11,BV11,BZ11,CD11,CH11,CL11,CP11,CT11,CX11,DB11) -> 1.7855203 | B11: 46762 | C11: =IF(MONTH(B11)=MONTH(B10),A11+C10,A11) -> 19.156993 | E11: 1095960 | F11: 1.7978877 | G11: =E11/24+2 -> 45667 | H11: =IF(MONTH(G11)=MONTH(G10),F11+H10,F11) -> 108.86185 | I11: 1087176 | J11: 0.98276311 | K11: =I11/24+2 -> 45301 | L11: =IF(MONTH(K11)=MONTH(K10),J11+L10,J11) -> 35.841693 | M11: 1078416 | N11: 2.676234 | O11: =M11/24+2 -> 44936 | P11: =IF(MONTH(O11)=MONTH(O10),N11+P10,N11) -> 105.90284 | Q11: 1069656 | R11: 1.839394 | S11: =Q11/24+2 -> 44571 | T11: =IF(MONTH(S11)=MONTH(S10),R11+T10,R11) -> 4.988215 | U11: 1060896 | V11: 0 | W11: =U11/24+2 -> 44206 | X11: =IF(MONTH(W11)=MONTH(W10),V11+X10,V11) -> 62.339378 | Y11: 1052112 | Z11: 0 | AA11: =Y11/24+2 -> 43840 | AB11: =IF(MONTH(AA11)=MONTH(AA10),Z11+AB10,Z11) -> 12.479446 | AD11: 0.12561698 | AE11: 43475 | AF11: =IF(MONTH(AE11)=MONTH(AE10),AF10+AD11,AD11) -> 70.099182 | AH11: 25.285294 | AI11: 43110 | AJ11: =IF(MONTH(AI11)=MONTH(AI10),AJ10+AH11,AH11) -> 106.96568 | AL11: 25.751089 | AM11: 42745 | AN11: =IF(MONTH(AM11)=MONTH(AM10),AN10+AL11,AL11) -> 178.13651 | AP11: 1.8927444 | AQ11: 42379 | AR11: =IF(MONTH(AQ11)=MONTH(AQ10),AR10+AP11,AP11) -> 124.33144 | AT11: 3.6993432 | AU11: 42014 | AV11: =IF(MONTH(AU11)=MONTH(AU10),AV10+AT11,AT11) -> 54.838193 | AX11: 1.397256 | AY11: 41649 | AZ11: =IF(MONTH(AY11)=MONTH(AY10),AZ10+AX11,AX11) -> 100.60429 | BB11: 13.505394 | BC11: 41284 | BD11: =IF(MONTH(BC11)=MONTH(BC10),BD10+BB11,BB11) -> 78.449556 | BF11: 0.51651901 | BG11: 40918 | BH11: =IF(MONTH(BG11)=MONTH(BG10),BH10+BF11,BF11) -> 76.494983 | BJ11: 18.320919 | BK11: 40553 | BL11: =IF(MONTH(BK11)=MONTH(BK10),BL10+BJ11,BJ11) -> 135.80152 | BN11: 0.43938023 | BO11: 40188 | BP11: =IF(MONTH(BO11)=MONTH(BO10),BP10+BN11,BN11) -> 5.5086493 | BR11: 2.7325616 | BS11: 39823 | BT11: =IF(MONTH(BS11)=MONTH(BS10),BT10+BR11,BR11) -> 24.792255 | BV11: 3.1901577 | BW11: 39457 | BX11: =IF(MONTH(BW11)=MONTH(BW10),BX10+BV11,BV11) -> 133.88499 | BZ11: 0 | CA11: 39092 | CB11: =IF(MONTH(CA11)=MONTH(CA10),CB10+BZ11,BZ11) -> 0.36321697 | CD11: 6.1779337 | CE11: 38727 | CF11: =IF(MONTH(CE11)=MONTH(CE10),CF10+CD11,CD11) -> 18.180664 | CH11: 0 | CI11: 38362 | CJ11: =IF(MONTH(CI11)=MONTH(CI10),CJ10+CH11,CH11) -> 5.8718138 | CL11: 0.47393218 | CM11: 37996 | CN11: =IF(MONTH(CM11)=MONTH(CM10),CN10+CL11,CL11) -> 41.912145 | CP11: 0.98616087 | CQ11: 37631 | CR11: =IF(MONTH(CQ11)=MONTH(CQ10),CR10+CP11,CP11) -> 33.600279 | CT11: 16.540285 | CU11: 37266 | CV11: =IF(MONTH(CU11)=MONTH(CU10),CV10+CT11,CT11) -> 49.425789 | CX11: 0.98990613 | CY11: 36901 | CZ11: =IF(MONTH(CY11)=MONTH(CY10),CZ10+CX11,CX11) -> 3.1598614 | DB11: 1.7731529 | DC11: 36535 | DD11: =IF(MONTH(DC11)=MONTH(DC10),DD10+DB11,DB11) -> 32.749888
A12: =MEDIAN(F12,J12,N12,R12,V12,Z12,AD12,AH12,AL12,AP12,AT12,AX12,BB12,BF12,BJ12,BN12,BR12,BV12,BZ12,CD12,CH12,CL12,CP12,CT12,CX12,DB12) -> 2.0563154 | B12: 46763 | C12: =IF(MONTH(B12)=MONTH(B11),A12+C11,A12) -> 21.213309 | E12: 1095984 | F12: 1.7986599 | G12: =E12/24+2 -> 45668 | H12: =IF(MONTH(G12)=MONTH(G11),F12+H11,F12) -> 110.66051 | I12: 1087200 | J12: 0.8281619 | K12: =I12/24+2 -> 45302 | L12: =IF(MONTH(K12)=MONTH(K11),J12+L11,J12) -> 36.669855 | M12: 1078440 | N12: 39.97636 | O12: =M12/24+2 -> 44937 | P12: =IF(MONTH(O12)=MONTH(O11),N12+P11,N12) -> 145.8792 | Q12: 1069680 | R12: 0.60438663 | S12: =Q12/24+2 -> 44572 | T12: =IF(MONTH(S12)=MONTH(S11),R12+T11,R12) -> 5.5926016 | U12: 1060920 | V12: 3.095757 | W12: =U12/24+2 -> 44207 | X12: =IF(MONTH(W12)=MONTH(W11),V12+X11,V12) -> 65.435135 | Y12: 1052136 | Z12: 5.2975497 | AA12: =Y12/24+2 -> 43841 | AB12: =IF(MONTH(AA12)=MONTH(AA11),Z12+AB11,Z12) -> 17.776995 | AD12: 0.063664287 | AE12: 43476 | AF12: =IF(MONTH(AE12)=MONTH(AE11),AF11+AD12,AD12) -> 70.162846 | AH12: 19.061888 | AI12: 43111 | AJ12: =IF(MONTH(AI12)=MONTH(AI11),AJ11+AH12,AH12) -> 126.02756 | AL12: 10.165463 | AM12: 42746 | AN12: =IF(MONTH(AM12)=MONTH(AM11),AN11+AL12,AL12) -> 188.30197 | AP12: 11.084519 | AQ12: 42380 | AR12: =IF(MONTH(AQ12)=MONTH(AQ11),AR11+AP12,AP12) -> 135.41596 | AT12: 1.9792407 | AU12: 42015 | AV12: =IF(MONTH(AU12)=MONTH(AU11),AV11+AT12,AT12) -> 56.817433 | AX12: 0.14926709 | AY12: 41650 | AZ12: =IF(MONTH(AY12)=MONTH(AY11),AZ11+AX12,AX12) -> 100.75356 | BB12: 0.11244597 | BC12: 41285 | BD12: =IF(MONTH(BC12)=MONTH(BC11),BD11+BB12,BB12) -> 78.562002 | BF12: 2.1333902 | BG12: 40919 | BH12: =IF(MONTH(BG12)=MONTH(BG11),BH11+BF12,BF12) -> 78.628373 | BJ12: 23.635172 | BK12: 40554 | BL12: =IF(MONTH(BK12)=MONTH(BK11),BL11+BJ12,BJ12) -> 159.43669 | BN12: 2.1582048 | BO12: 40189 | BP12: =IF(MONTH(BO12)=MONTH(BO11),BP11+BN12,BN12) -> 7.6668541 | BR12: 0.34635553 | BS12: 39824 | BT12: =IF(MONTH(BS12)=MONTH(BS11),BT11+BR12,BR12) -> 25.138611 | BV12: 32.542561 | BW12: 39458 | BX12: =IF(MONTH(BW12)=MONTH(BW11),BX11+BV12,BV12) -> 166.42755 | BZ12: 0 | CA12: 39093 | CB12: =IF(MONTH(CA12)=MONTH(CA11),CB11+BZ12,BZ12) -> 0.36321697 | CD12: 0.069140591 | CE12: 38728 | CF12: =IF(MONTH(CE12)=MONTH(CE11),CF11+CD12,CD12) -> 18.249805 | CH12: 0 | CI12: 38363 | CJ12: =IF(MONTH(CI12)=MONTH(CI11),CJ11+CH12,CH12) -> 5.8718138 | CL12: 0.35744509 | CM12: 37997 | CN12: =IF(MONTH(CM12)=MONTH(CM11),CN11+CL12,CL12) -> 42.26959 | CP12: 15.926776 | CQ12: 37632 | CR12: =IF(MONTH(CQ12)=MONTH(CQ11),CR11+CP12,CP12) -> 49.527055 | CT12: 0.98433191 | CU12: 37267 | CV12: =IF(MONTH(CU12)=MONTH(CU11),CV11+CT12,CT12) -> 50.410121 | CX12: 14.98807 | CY12: 36902 | CZ12: =IF(MONTH(CY12)=MONTH(CY11),CZ11+CX12,CX12) -> 18.147931 | DB12: 3.0090466 | DC12: 36536 | DD12: =IF(MONTH(DC12)=MONTH(DC11),DD11+DB12,DB12) -> 35.758935
A13: =MEDIAN(F13,J13,N13,R13,V13,Z13,AD13,AH13,AL13,AP13,AT13,AX13,BB13,BF13,BJ13,BN13,BR13,BV13,BZ13,CD13,CH13,CL13,CP13,CT13,CX13,DB13) -> 1.8132972 | B13: 46764 | C13: =IF(MONTH(B13)=MONTH(B12),A13+C12,A13) -> 23.026606 | E13: 1096008 | F13: 1.5331109 | G13: =E13/24+2 -> 45669 | H13: =IF(MONTH(G13)=MONTH(G12),F13+H12,F13) -> 112.19362 | I13: 1087224 | J13: 1.7107038 | K13: =I13/24+2 -> 45303 | L13: =IF(MONTH(K13)=MONTH(K12),J13+L12,J13) -> 38.380559 | M13: 1078464 | N13: 31.69393 | O13: =M13/24+2 -> 44938 | P13: =IF(MONTH(O13)=MONTH(O12),N13+P12,N13) -> 177.57313 | Q13: 1069704 | R13: 0.84554845 | S13: =Q13/24+2 -> 44573 | T13: =IF(MONTH(S13)=MONTH(S12),R13+T12,R13) -> 6.43815 | U13: 1060944 | V13: 5.5212169 | W13: =U13/24+2 -> 44208 | X13: =IF(MONTH(W13)=MONTH(W12),V13+X12,V13) -> 70.956352 | Y13: 1052160 | Z13: 0.90930253 | AA13: =Y13/24+2 -> 43842 | AB13: =IF(MONTH(AA13)=MONTH(AA12),Z13+AB12,Z13) -> 18.686298 | AD13: 3.7405472 | AE13: 43477 | AF13: =IF(MONTH(AE13)=MONTH(AE12),AF12+AD13,AD13) -> 73.903394 | AH13: 26.998062 | AI13: 43112 | AJ13: =IF(MONTH(AI13)=MONTH(AI12),AJ12+AH13,AH13) -> 153.02563 | AL13: 1.9158906 | AM13: 42747 | AN13: =IF(MONTH(AM13)=MONTH(AM12),AN12+AL13,AL13) -> 190.21786 | AP13: 1.1840625 | AQ13: 42381 | AR13: =IF(MONTH(AQ13)=MONTH(AQ12),AR12+AP13,AP13) -> 136.60002 | AT13: 4.7599611 | AU13: 42016 | AV13: =IF(MONTH(AU13)=MONTH(AU12),AV12+AT13,AT13) -> 61.577395 | AX13: 0 | AY13: 41651 | AZ13: =IF(MONTH(AY13)=MONTH(AY12),AZ12+AX13,AX13) -> 100.75356 | BB13: 1.9798648 | BC13: 41286 | BD13: =IF(MONTH(BC13)=MONTH(BC12),BD12+BB13,BB13) -> 80.541867 | BF13: 5.365705 | BG13: 40920 | BH13: =IF(MONTH(BG13)=MONTH(BG12),BH12+BF13,BF13) -> 83.994078 | BJ13: 14.561442 | BK13: 40555 | BL13: =IF(MONTH(BK13)=MONTH(BK12),BL12+BJ13,BJ13) -> 173.99813 | BN13: 0.72767878 | BO13: 40190 | BP13: =IF(MONTH(BO13)=MONTH(BO12),BP12+BN13,BN13) -> 8.3945329 | BR13: 0 | BS13: 39825 | BT13: =IF(MONTH(BS13)=MONTH(BS12),BT12+BR13,BR13) -> 25.138611 | BV13: 33.951138 | BW13: 39459 | BX13: =IF(MONTH(BW13)=MONTH(BW12),BX12+BV13,BV13) -> 200.37869 | BZ13: 0 | CA13: 39094 | CB13: =IF(MONTH(CA13)=MONTH(CA12),CB12+BZ13,BZ13) -> 0.36321697 | CD13: 9.8052464 | CE13: 38729 | CF13: =IF(MONTH(CE13)=MONTH(CE12),CF12+CD13,CD13) -> 28.055051 | CH13: 0 | CI13: 38364 | CJ13: =IF(MONTH(CI13)=MONTH(CI12),CJ12+CH13,CH13) -> 5.8718138 | CL13: 0.56778103 | CM13: 37998 | CN13: =IF(MONTH(CM13)=MONTH(CM12),CN12+CL13,CL13) -> 42.837371 | CP13: 3.3626926 | CQ13: 37633 | CR13: =IF(MONTH(CQ13)=MONTH(CQ12),CR12+CP13,CP13) -> 52.889748 | CT13: 11.123761 | CU13: 37268 | CV13: =IF(MONTH(CU13)=MONTH(CU12),CV12+CT13,CT13) -> 61.533882 | CX13: 0.088576026 | CY13: 36903 | CZ13: =IF(MONTH(CY13)=MONTH(CY12),CZ12+CX13,CX13) -> 18.236507 | DB13: 0.9639594 | DC13: 36537 | DD13: =IF(MONTH(DC13)=MONTH(DC12),DD12+DB13,DB13) -> 36.722894
A14: =MEDIAN(F14,J14,N14,R14,V14,Z14,AD14,AH14,AL14,AP14,AT14,AX14,BB14,BF14,BJ14,BN14,BR14,BV14,BZ14,CD14,CH14,CL14,CP14,CT14,CX14,DB14) -> 0.88085443 | B14: 46765 | C14: =IF(MONTH(B14)=MONTH(B13),A14+C13,A14) -> 23.90746 | E14: 1096032 | F14: 0 | G14: =E14/24+2 -> 45670 | H14: =IF(MONTH(G14)=MONTH(G13),F14+H13,F14) -> 112.19362 | I14: 1087248 | J14: 22.472433 | K14: =I14/24+2 -> 45304 | L14: =IF(MONTH(K14)=MONTH(K13),J14+L13,J14) -> 60.852992 | M14: 1078488 | N14: 0.61846703 | O14: =M14/24+2 -> 44939 | P14: =IF(MONTH(O14)=MONTH(O13),N14+P13,N14) -> 178.19159 | Q14: 1069728 | R14: 1.3704342 | S14: =Q14/24+2 -> 44574 | T14: =IF(MONTH(S14)=MONTH(S13),R14+T13,R14) -> 7.8085842 | U14: 1060968 | V14: 8.0969973 | W14: =U14/24+2 -> 44209 | X14: =IF(MONTH(W14)=MONTH(W13),V14+X13,V14) -> 79.053349 | Y14: 1052184 | Z14: 10.991772 | AA14: =Y14/24+2 -> 43843 | AB14: =IF(MONTH(AA14)=MONTH(AA13),Z14+AB13,Z14) -> 29.67807 | AD14: 15.627919 | AE14: 43478 | AF14: =IF(MONTH(AE14)=MONTH(AE13),AF13+AD14,AD14) -> 89.531313 | AH14: 0.02018493 | AI14: 43113 | AJ14: =IF(MONTH(AI14)=MONTH(AI13),AJ13+AH14,AH14) -> 153.04581 | AL14: 0.97335017 | AM14: 42748 | AN14: =IF(MONTH(AM14)=MONTH(AM13),AN13+AL14,AL14) -> 191.19122 | AP14: 0.78835869 | AQ14: 42382 | AR14: =IF(MONTH(AQ14)=MONTH(AQ13),AR13+AP14,AP14) -> 137.38838 | AT14: 5.8687849 | AU14: 42017 | AV14: =IF(MONTH(AU14)=MONTH(AU13),AV13+AT14,AT14) -> 67.446179 | AX14: 0 | AY14: 41652 | AZ14: =IF(MONTH(AY14)=MONTH(AY13),AZ13+AX14,AX14) -> 100.75356 | BB14: 0.02411703 | BC14: 41287 | BD14: =IF(MONTH(BC14)=MONTH(BC13),BD13+BB14,BB14) -> 80.565984 | BF14: 40.985336 | BG14: 40921 | BH14: =IF(MONTH(BG14)=MONTH(BG13),BH13+BF14,BF14) -> 124.97941 | BJ14: 3.5871129 | BK14: 40556 | BL14: =IF(MONTH(BK14)=MONTH(BK13),BL13+BJ14,BJ14) -> 177.58524 | BN14: 0 | BO14: 40191 | BP14: =IF(MONTH(BO14)=MONTH(BO13),BP13+BN14,BN14) -> 8.3945329 | BR14: 0.073022753 | BS14: 39826 | BT14: =IF(MONTH(BS14)=MONTH(BS13),BT13+BR14,BR14) -> 25.211634 | BV14: 1.205346 | BW14: 39460 | BX14: =IF(MONTH(BW14)=MONTH(BW13),BX13+BV14,BV14) -> 201.58403 | BZ14: 6.5541663 | CA14: 39095 | CB14: =IF(MONTH(CA14)=MONTH(CA13),CB13+BZ14,BZ14) -> 6.9173833 | CD14: 0 | CE14: 38730 | CF14: =IF(MONTH(CE14)=MONTH(CE13),CF13+CD14,CD14) -> 28.055051 | CH14: 0.19930002 | CI14: 38365 | CJ14: =IF(MONTH(CI14)=MONTH(CI13),CJ13+CH14,CH14) -> 6.0711138 | CL14: 0.25547475 | CM14: 37999 | CN14: =IF(MONTH(CM14)=MONTH(CM13),CN13+CL14,CL14) -> 43.092846 | CP14: 0.062944241 | CQ14: 37634 | CR14: =IF(MONTH(CQ14)=MONTH(CQ13),CR13+CP14,CP14) -> 52.952692 | CT14: 0.067625761 | CU14: 37269 | CV14: =IF(MONTH(CU14)=MONTH(CU13),CV13+CT14,CT14) -> 61.601508 | CX14: 2.3686621 | CY14: 36904 | CZ14: =IF(MONTH(CY14)=MONTH(CY13),CZ13+CX14,CX14) -> 20.605169 | DB14: 1.2354305 | DC14: 36538 | DD14: =IF(MONTH(DC14)=MONTH(DC13),DD13+DB14,DB14) -> 37.958325
... A57: =MEDIAN(F57,J57,N57,R57,V57,Z57,AD57,AH57,AL57,AP57,AT57,AX57,BB57,BF57,BJ57,BN57,BR57,BV57,BZ57,CD57,CH57,CL57,CP57,CT57,CX57,DB57) -> 3.9464799 | B57: 46808 | C57: =IF(MONTH(B57)=MONTH(B56),A57+C56,A57) -> 81.785143 | E57: 1097064 | F57: 7.4619341 | G57: =E57/24+2 -> 45713 | H57: =IF(MONTH(G57)=MONTH(G56),F57+H56,F57) -> 403.30016 | I57: 1088280 | J57: 0.047261946 | K57: =I57/24+2 -> 45347 | L57: =IF(MONTH(K57)=MONTH(K56),J57+L56,J57) -> 193.29893 | M57: 1079520 | N57: 0 | O57: =M57/24+2 -> 44982 | P57: =IF(MONTH(O57)=MONTH(O56),N57+P56,N57) -> 175.6766 | Q57: 1070760 | R57: 15.31821 | S57: =Q57/24+2 -> 44617 | T57: =IF(MONTH(S57)=MONTH(S56),R57+T56,R57) -> 103.07298 | U57: 1062000 | V57: 3.6598966 | W57: =U57/24+2 -> 44252 | X57: =IF(MONTH(W57)=MONTH(W56),V57+X56,V57) -> 165.37386 | Y57: 1053216 | Z57: 0 | AA57: =Y57/24+2 -> 43886 | AB57: =IF(MONTH(AA57)=MONTH(AA56),Z57+AB56,Z57) -> 117.81982 | AD57: 15.249414 | AE57: 43521 | AF57: =IF(MONTH(AE57)=MONTH(AE56),AF56+AD57,AD57) -> 241.55825 | AH57: 0 | AI57: 43156 | AJ57: =IF(MONTH(AI57)=MONTH(AI56),AJ56+AH57,AH57) -> 147.92683 | AL57: 10.410373 | AM57: 42791 | AN57: =IF(MONTH(AM57)=MONTH(AM56),AN56+AL57,AL57) -> 210.14899 | AP57: 15.61379 | AQ57: 42425 | AR57: =IF(MONTH(AQ57)=MONTH(AQ56),AR56+AP57,AP57) -> 231.33376 | AT57: 4.2330632 | AU57: 42060 | AV57: =IF(MONTH(AU57)=MONTH(AU56),AV56+AT57,AT57) -> 300.36375 | AX57: 21.726185 | AY57: 41695 | AZ57: =IF(MONTH(AY57)=MONTH(AY56),AZ56+AX57,AX57) -> 152.30626 | BB57: 1.6281322 | BC57: 41330 | BD57: =IF(MONTH(BC57)=MONTH(BC56),BD56+BB57,BB57) -> 207.52735 | BF57: 0.77820766 | BG57: 40964 | BH57: =IF(MONTH(BG57)=MONTH(BG56),BH56+BF57,BF57) -> 306.998 | BJ57: 34.710743 | BK57: 40599 | BL57: =IF(MONTH(BK57)=MONTH(BK56),BL56+BJ57,BJ57) -> 206.62055 | BN57: 16.659321 | BO57: 40234 | BP57: =IF(MONTH(BO57)=MONTH(BO56),BP56+BN57,BN57) -> 156.43783 | BR57: 1.5744439 | BS57: 39869 | BT57: =IF(MONTH(BS57)=MONTH(BS56),BT56+BR57,BR57) -> 309.10698 | BV57: 22.885468 | BW57: 39503 | BX57: =IF(MONTH(BW57)=MONTH(BW56),BX56+BV57,BV57) -> 365.95172 | BZ57: 1.4573263 | CA57: 39138 | CB57: =IF(MONTH(CA57)=MONTH(CA56),CB56+BZ57,BZ57) -> 10.1099 | CD57: 7.4594622 | CE57: 38773 | CF57: =IF(MONTH(CE57)=MONTH(CE56),CF56+CD57,CD57) -> 254.98859 | CH57: 0 | CI57: 38408 | CJ57: =IF(MONTH(CI57)=MONTH(CI56),CJ56+CH57,CH57) -> 46.30911 | CL57: 13.076097 | CM57: 38042 | CN57: =IF(MONTH(CM57)=MONTH(CM56),CN56+CL57,CL57) -> 69.047099 | CP57: 1.9868189 | CQ57: 37677 | CR57: =IF(MONTH(CQ57)=MONTH(CQ56),CR56+CP57,CP57) -> 75.336824 | CT57: 0.11222434 | CU57: 37312 | CV57: =IF(MONTH(CU57)=MONTH(CU56),CV56+CT57,CT57) -> 72.547484 | CX57: 0 | CY57: 36947 | CZ57: =IF(MONTH(CY57)=MONTH(CY56),CZ56+CX57,CX57) -> 53.836143 | DB57: 24.840916 | DC57: 36581 | DD57: =IF(MONTH(DC57)=MONTH(DC56),DD56+DB57,DB57) -> 113.58586
A58: =MEDIAN(F58,J58,N58,R58,V58,Z58,AD58,AH58,AL58,AP58,AT58,AX58,BB58,BF58,BJ58,BN58,BR58,BV58,BZ58,CD58,CH58,CL58,CP58,CT58,CX58,DB58) -> 5.9895411 | B58: 46809 | C58: =IF(MONTH(B58)=MONTH(B57),A58+C57,A58) -> 87.774684 | E58: 1097088 | F58: 34.35994 | G58: =E58/24+2 -> 45714 | H58: =IF(MONTH(G58)=MONTH(G57),F58+H57,F58) -> 437.66009 | I58: 1088304 | J58: 3.3103635 | K58: =I58/24+2 -> 45348 | L58: =IF(MONTH(K58)=MONTH(K57),J58+L57,J58) -> 196.6093 | M58: 1079544 | N58: 0 | O58: =M58/24+2 -> 44983 | P58: =IF(MONTH(O58)=MONTH(O57),N58+P57,N58) -> 175.6766 | Q58: 1070784 | R58: 19.478802 | S58: =Q58/24+2 -> 44618 | T58: =IF(MONTH(S58)=MONTH(S57),R58+T57,R58) -> 122.55178 | U58: 1062024 | V58: 5.9895411 | W58: =U58/24+2 -> 44253 | X58: =IF(MONTH(W58)=MONTH(W57),V58+X57,V58) -> 171.3634 | Y58: 1053240 | Z58: 0.6617468 | AA58: =Y58/24+2 -> 43887 | AB58: =IF(MONTH(AA58)=MONTH(AA57),Z58+AB57,Z58) -> 118.48156 | AD58: 0.73403019 | AE58: 43522 | AF58: =IF(MONTH(AE58)=MONTH(AE57),AF57+AD58,AD58) -> 242.29228 | AH58: 0 | AI58: 43157 | AJ58: =IF(MONTH(AI58)=MONTH(AI57),AJ57+AH58,AH58) -> 147.92683 | AL58: 47.729031 | AM58: 42792 | AN58: =IF(MONTH(AM58)=MONTH(AM57),AN57+AL58,AL58) -> 257.87802 | AP58: 9.5041399 | AQ58: 42426 | AR58: =IF(MONTH(AQ58)=MONTH(AQ57),AR57+AP58,AP58) -> 240.8379 | AT58: 26.821844 | AU58: 42061 | AV58: =IF(MONTH(AU58)=MONTH(AU57),AV57+AT58,AT58) -> 327.18559 | AX58: 7.9057722 | AY58: 41696 | AZ58: =IF(MONTH(AY58)=MONTH(AY57),AZ57+AX58,AX58) -> 160.21203 | BB58: 0.964764 | BC58: 41331 | BD58: =IF(MONTH(BC58)=MONTH(BC57),BD57+BB58,BB58) -> 208.49211 | BF58: 13.70842 | BG58: 40965 | BH58: =IF(MONTH(BG58)=MONTH(BG57),BH57+BF58,BF58) -> 320.70642 | BJ58: 4.5257673 | BK58: 40600 | BL58: =IF(MONTH(BK58)=MONTH(BK57),BL57+BJ58,BJ58) -> 211.14632 | BN58: 31.146774 | BO58: 40235 | BP58: =IF(MONTH(BO58)=MONTH(BO57),BP57+BN58,BN58) -> 187.58461 | BR58: 1.0095288 | BS58: 39870 | BT58: =IF(MONTH(BS58)=MONTH(BS57),BT57+BR58,BR58) -> 310.11651 | BV58: 12.619711 | BW58: 39504 | BX58: =IF(MONTH(BW58)=MONTH(BW57),BX57+BV58,BV58) -> 378.57143 | CA58: 39139 | CB58: =IF(MONTH(CA58)=MONTH(CA57),CB57+BZ58,BZ58) -> 10.1099 | CD58: 26.701168 | CE58: 38774 | CF58: =IF(MONTH(CE58)=MONTH(CE57),CF57+CD58,CD58) -> 281.68976 | CH58: 0 | CI58: 38409 | CJ58: =IF(MONTH(CI58)=MONTH(CI57),CJ57+CH58,CH58) -> 46.30911 | CL58: 10.794229 | CM58: 38043 | CN58: =IF(MONTH(CM58)=MONTH(CM57),CN57+CL58,CL58) -> 79.841327 | CP58: 3.0437202 | CQ58: 37678 | CR58: =IF(MONTH(CQ58)=MONTH(CQ57),CR57+CP58,CP58) -> 78.380544 | CT58: 0.21700391 | CU58: 37313 | CV58: =IF(MONTH(CU58)=MONTH(CU57),CV57+CT58,CT58) -> 72.764488 | CX58: 0.81610948 | CY58: 36948 | CZ58: =IF(MONTH(CY58)=MONTH(CY57),CZ57+CX58,CX58) -> 54.652252 | DB58: 20.123989 | DC58: 36582 | DD58: =IF(MONTH(DC58)=MONTH(DC57),DD57+DB58,DB58) -> 133.70985
A59: =MEDIAN(F59,J59,N59,R59,V59,Z59,AD59,AH59,AL59,AP59,AT59,AX59,BB59,BF59,BJ59,BN59,BR59,BV59,BZ59,CD59,CH59,CL59,CP59,CT59,CX59,DB59) -> 4.5221152 | B59: 46810 | C59: =IF(MONTH(B59)=MONTH(B58),A59+C58,A59) -> 92.296799 | E59: 1097112 | F59: 11.64461 | G59: =E59/24+2 -> 45715 | H59: =IF(MONTH(G59)=MONTH(G58),F59+H58,F59) -> 449.30471 | I59: 1088328 | J59: 6.4926057 | K59: =I59/24+2 -> 45349 | L59: =IF(MONTH(K59)=MONTH(K58),J59+L58,J59) -> 203.1019 | M59: 1079568 | N59: 1.5532963 | O59: =M59/24+2 -> 44984 | P59: =IF(MONTH(O59)=MONTH(O58),N59+P58,N59) -> 177.22989 | Q59: 1070808 | R59: 26.758087 | S59: =Q59/24+2 -> 44619 | T59: =IF(MONTH(S59)=MONTH(S58),R59+T58,R59) -> 149.30987 | U59: 1062048 | V59: 3.5218198 | W59: =U59/24+2 -> 44254 | X59: =IF(MONTH(W59)=MONTH(W58),V59+X58,V59) -> 174.88522 | Y59: 1053264 | Z59: 2.6258051 | AA59: =Y59/24+2 -> 43888 | AB59: =IF(MONTH(AA59)=MONTH(AA58),Z59+AB58,Z59) -> 121.10737 | AD59: 0.060415804 | AE59: 43523 | AF59: =IF(MONTH(AE59)=MONTH(AE58),AF58+AD59,AD59) -> 242.3527 | AH59: 2.5957978 | AI59: 43158 | AJ59: =IF(MONTH(AI59)=MONTH(AI58),AJ58+AH59,AH59) -> 150.52263 | AL59: 7.7807193 | AM59: 42793 | AN59: =IF(MONTH(AM59)=MONTH(AM58),AN58+AL59,AL59) -> 265.65874 | AP59: 4.3871651 | AQ59: 42427 | AR59: =IF(MONTH(AQ59)=MONTH(AQ58),AR58+AP59,AP59) -> 245.22506 | AT59: 0.35962141 | AU59: 42062 | AV59: =IF(MONTH(AU59)=MONTH(AU58),AV58+AT59,AT59) -> 327.54521 | AX59: 0.71143448 | AY59: 41697 | AZ59: =IF(MONTH(AY59)=MONTH(AY58),AZ58+AX59,AX59) -> 160.92346 | BB59: 15.109407 | BC59: 41332 | BD59: =IF(MONTH(BC59)=MONTH(BC58),BD58+BB59,BB59) -> 223.60152 | BF59: 14.621469 | BG59: 40966 | BH59: =IF(MONTH(BG59)=MONTH(BG58),BH58+BF59,BF59) -> 335.32789 | BJ59: 3.1094816 | BK59: 40601 | BL59: =IF(MONTH(BK59)=MONTH(BK58),BL58+BJ59,BJ59) -> 214.2558 | BN59: 5.2437572 | BO59: 40236 | BP59: =IF(MONTH(BO59)=MONTH(BO58),BP58+BN59,BN59) -> 192.82836 | BR59: 11.378564 | BS59: 39871 | BT59: =IF(MONTH(BS59)=MONTH(BS58),BT58+BR59,BR59) -> 321.49507 | BV59: 12.928409 | BW59: 39505 | BX59: =IF(MONTH(BW59)=MONTH(BW58),BX58+BV59,BV59) -> 391.49984 | BZ59: 1.4574493 | CA59: 39140 | CB59: =IF(MONTH(CA59)=MONTH(CA58),CB58+BZ59,BZ59) -> 11.567349 | CD59: 0.2334154 | CE59: 38775 | CF59: =IF(MONTH(CE59)=MONTH(CE58),CF58+CD59,CD59) -> 281.92318 | CH59: 1.875191 | CI59: 38410 | CJ59: =IF(MONTH(CI59)=MONTH(CI58),CJ58+CH59,CH59) -> 48.184301 | CL59: 2.2396643 | CM59: 38044 | CN59: =IF(MONTH(CM59)=MONTH(CM58),CN58+CL59,CL59) -> 82.080992 | CP59: 44.354195 | CQ59: 37679 | CR59: =IF(MONTH(CQ59)=MONTH(CQ58),CR58+CP59,CP59) -> 122.73474 | CT59: 16.947033 | CU59: 37314 | CV59: =IF(MONTH(CU59)=MONTH(CU58),CV58+CT59,CT59) -> 89.711521 | CX59: 4.6570654 | CY59: 36949 | CZ59: =IF(MONTH(CY59)=MONTH(CY58),CZ58+CX59,CX59) -> 59.309318 | DB59: 8.376936 | DC59: 36583 | DD59: =IF(MONTH(DC59)=MONTH(DC58),DD58+DB59,DB59) -> 142.08679
A60: =MEDIAN(F60,J60,N60,R60,V60,Z60,AD60,AH60,AL60,AP60,AT60,AX60,BB60,BF60,BJ60,BN60,BR60,BV60,BZ60,CD60,CH60,CL60,CP60,CT60,CX60,DB60) -> 3.5287594 | B60: 46811 | C60: =IF(MONTH(B60)=MONTH(B59),A60+C59,A60) -> 95.825558 | E60: 1097136 | F60: 24.387897 | G60: =E60/24+2 -> 45716 | H60: =IF(MONTH(G60)=MONTH(G59),F60+H59,F60) -> 473.6926 | I60: 1088352 | J60: 3.8753941 | K60: =I60/24+2 -> 45350 | L60: =IF(MONTH(K60)=MONTH(K59),J60+L59,J60) -> 206.9773 | M60: 1079592 | N60: 12.675174 | O60: =M60/24+2 -> 44985 | P60: =IF(MONTH(O60)=MONTH(O59),N60+P59,N60) -> 189.90507 | Q60: 1070832 | R60: 51.725643 | S60: =Q60/24+2 -> 44620 | T60: =IF(MONTH(S60)=MONTH(S59),R60+T59,R60) -> 201.03551 | U60: 1062072 | V60: 12.954635 | W60: =U60/24+2 -> 44255 | X60: =IF(MONTH(W60)=MONTH(W59),V60+X59,V60) -> 187.83986 | Y60: 1053288 | Z60: 1.3197134 | AA60: =Y60/24+2 -> 43889 | AB60: =IF(MONTH(AA60)=MONTH(AA59),Z60+AB59,Z60) -> 122.42708 | AD60: 2.3366609 | AE60: 43524 | AF60: =IF(MONTH(AE60)=MONTH(AE59),AF59+AD60,AD60) -> 244.68936 | AH60: 0.78507632 | AI60: 43159 | AJ60: =IF(MONTH(AI60)=MONTH(AI59),AJ59+AH60,AH60) -> 151.30771 | AL60: 0.096494392 | AM60: 42794 | AN60: =IF(MONTH(AM60)=MONTH(AM59),AN59+AL60,AL60) -> 265.75524 | AP60: 1.3143451 | AQ60: 42428 | AR60: =IF(MONTH(AQ60)=MONTH(AQ59),AR59+AP60,AP60) -> 246.53941 | AT60: 10.859775 | AU60: 42063 | AV60: =IF(MONTH(AU60)=MONTH(AU59),AV59+AT60,AT60) -> 338.40499 | AX60: 26.696308 | AY60: 41698 | AZ60: =IF(MONTH(AY60)=MONTH(AY59),AZ59+AX60,AX60) -> 187.61977 | BB60: 31.422207 | BC60: 41333 | BD60: =IF(MONTH(BC60)=MONTH(BC59),BD59+BB60,BB60) -> 255.02373 | BF60: 4.4682512 | BG60: 40967 | BH60: =IF(MONTH(BG60)=MONTH(BG59),BH59+BF60,BF60) -> 339.79614 | BJ60: 2.0595353 | BK60: 40602 | BL60: =IF(MONTH(BK60)=MONTH(BK59),BL59+BJ60,BJ60) -> 216.31533 | BN60: 1.948745 | BO60: 40237 | BP60: =IF(MONTH(BO60)=MONTH(BO59),BP59+BN60,BN60) -> 194.77711 | BR60: 14.309555 | BS60: 39872 | BT60: =IF(MONTH(BS60)=MONTH(BS59),BT59+BR60,BR60) -> 335.80463 | BV60: 1.6279004 | BW60: 39506 | BX60: =IF(MONTH(BW60)=MONTH(BW59),BX59+BV60,BV60) -> 393.12774 | BZ60: 1.4575243 | CA60: 39141 | CB60: =IF(MONTH(CA60)=MONTH(CA59),CB59+BZ60,BZ60) -> 13.024874 | CD60: 7.3036909 | CE60: 38776 | CF60: =IF(MONTH(CE60)=MONTH(CE59),CF59+CD60,CD60) -> 289.22687 | CH60: 1.8605143 | CI60: 38411 | CJ60: =IF(MONTH(CI60)=MONTH(CI59),CJ59+CH60,CH60) -> 50.044815 | CL60: 0.089633867 | CM60: 38045 | CN60: =IF(MONTH(CM60)=MONTH(CM59),CN59+CL60,CL60) -> 82.170626 | CP60: 4.017272 | CQ60: 37680 | CR60: =IF(MONTH(CQ60)=MONTH(CQ59),CR59+CP60,CP60) -> 126.75201 | CT60: 3.1821246 | CU60: 37315 | CV60: =IF(MONTH(CU60)=MONTH(CU59),CV59+CT60,CT60) -> 92.893645 | CX60: 1.6142737 | CY60: 36950 | CZ60: =IF(MONTH(CY60)=MONTH(CY59),CZ59+CX60,CX60) -> 60.923591 | DB60: 17.680935 | DC60: 36584 | DD60: =IF(MONTH(DC60)=MONTH(DC59),DD59+DB60,DB60) -> 159.76772
A61: =MEDIAN(F61,J61,N61,R61,V61,Z61,AD61,AH61,AL61,AP61,AT61,AX61,BB61,BF61,BJ61,BN61,BR61,BV61,BZ61,CD61,CH61,CL61,CP61,CT61,CX61,DB61) -> 4.1718612 | B61: 46812 | C61: =IF(MONTH(B61)=MONTH(B60),A61+C60,A61) -> 99.99742 | I61: 1088376 | J61: 4.1718612 | K61: =I61/24+2 -> 45351 | L61: =IF(MONTH(K61)=MONTH(K60),J61+L60,J61) -> 211.14916 | P61: =IF(MONTH(O61)=MONTH(O60),N61+P60,N61) -> 0 | T61: =IF(MONTH(S61)=MONTH(S60),R61+T60,R61) -> 0 | X61: =IF(MONTH(W61)=MONTH(W60),V61+X60,V61) -> 0 | Y61: 1053312 | Z61: 0 | AA61: =Y61/24+2 -> 43890 | AB61: =IF(MONTH(AA61)=MONTH(AA60),Z61+AB60,Z61) -> 122.42708 | AP61: 11.269178 | AQ61: 42429 | AR61: =IF(MONTH(AQ61)=MONTH(AQ60),AR60+AP61,AP61) -> 257.80858 | BF61: 0.042000499 | BG61: 40968 | BH61: =IF(MONTH(BG61)=MONTH(BG60),BH60+BF61,BF61) -> 339.83814 | BV61: 6.2508068 | BW61: 39507 | BX61: =IF(MONTH(BW61)=MONTH(BW60),BX60+BV61,BV61) -> 399.37854 | CL61: 3.2177212 | CM61: 38046 | CN61: =IF(MONTH(CM61)=MONTH(CM60),CN60+CL61,CL61) -> 85.388347 | DB61: 20.478739 | DC61: 36585 | DD61: =IF(MONTH(DC61)=MONTH(DC60),DD60+DB61,DB61) -> 180.24646
A62: =MEDIAN(F62,J62,N62,R62,V62,Z62,AD62,AH62,AL62,AP62,AT62,AX62,BB62,BF62,BJ62,BN62,BR62,BV62,BZ62,CD62,CH62,CL62,CP62,CT62,CX62,DB62) -> 2.2818611 | B62: 46813 | C62: =IF(MONTH(B62)=MONTH(B61),A62+C61,A62) -> 2.2818611 | E62: 1097160 | F62: 0.02261073 | G62: =E62/24+2 -> 45717 | H62: =IF(MONTH(G62)=MONTH(G61),F62+H61,F62) -> 0.02261073 | I62: 1088400 | J62: 2.9723041 | K62: =I62/24+2 -> 45352 | L62: =IF(MONTH(K62)=MONTH(K61),J62+L61,J62) -> 2.9723041 | M62: 1079616 | N62: 9.1260777 | O62: =M62/24+2 -> 44986 | P62: =IF(MONTH(O62)=MONTH(O61),N62+P61,N62) -> 9.1260777 | Q62: 1070856 | R62: 0.54353207 | S62: =Q62/24+2 -> 44621 | T62: =IF(MONTH(S62)=MONTH(S61),R62+T61,R62) -> 0.54353207 | U62: 1062096 | V62: 27.853506 | W62: =U62/24+2 -> 44256 | X62: =IF(MONTH(W62)=MONTH(W61),V62+X61,V62) -> 27.853506 | Y62: 1053336 | Z62: 1.5914181 | AA62: =Y62/24+2 -> 43891 | AB62: =IF(MONTH(AA62)=MONTH(AA61),Z62+AB61,Z62) -> 1.5914181 | AD62: 0.46650037 | AE62: 43525 | AF62: =IF(MONTH(AE62)=MONTH(AE61),AF61+AD62,AD62) -> 0.46650037 | AH62: 33.46106 | AI62: 43160 | AJ62: =IF(MONTH(AI62)=MONTH(AI61),AJ61+AH62,AH62) -> 33.46106 | AL62: 0.41116843 | AM62: 42795 | AN62: =IF(MONTH(AM62)=MONTH(AM61),AN61+AL62,AL62) -> 0.41116843 | AP62: 0.89707607 | AQ62: 42430 | AR62: =IF(MONTH(AQ62)=MONTH(AQ61),AR61+AP62,AP62) -> 0.89707607 | AT62: 16.002041 | AU62: 42064 | AV62: =IF(MONTH(AU62)=MONTH(AU61),AV61+AT62,AT62) -> 16.002041 | AX62: 0 | AY62: 41699 | AZ62: =IF(MONTH(AY62)=MONTH(AY61),AZ61+AX62,AX62) -> 0 | BB62: 4.5770879 | BC62: 41334 | BD62: =IF(MONTH(BC62)=MONTH(BC61),BD61+BB62,BB62) -> 4.5770879 | BF62: 12.803818 | BG62: 40969 | BH62: =IF(MONTH(BG62)=MONTH(BG61),BH61+BF62,BF62) -> 12.803818 | BJ62: 10.302898 | BK62: 40603 | BL62: =IF(MONTH(BK62)=MONTH(BK61),BL61+BJ62,BJ62) -> 10.302898 | BN62: 1.2807543 | BO62: 40238 | BP62: =IF(MONTH(BO62)=MONTH(BO61),BP61+BN62,BN62) -> 1.2807543 | BR62: 4.0011511 | BS62: 39873 | BT62: =IF(MONTH(BS62)=MONTH(BS61),BT61+BR62,BR62) -> 4.0011511 | BV62: 0 | BW62: 39508 | BX62: =IF(MONTH(BW62)=MONTH(BW61),BX61+BV62,BV62) -> 0 | BZ62: 0 | CA62: 39142 | CB62: =IF(MONTH(CA62)=MONTH(CA61),CB61+BZ62,BZ62) -> 0 | CD62: 0 | CE62: 38777 | CF62: =IF(MONTH(CE62)=MONTH(CE61),CF61+CD62,CD62) -> 0 | CH62: 0.27474427 | CI62: 38412 | CJ62: =IF(MONTH(CI62)=MONTH(CI61),CJ61+CH62,CH62) -> 0.27474427 | CL62: 6.6825094 | CM62: 38047 | CN62: =IF(MONTH(CM62)=MONTH(CM61),CN61+CL62,CL62) -> 6.6825094 | CP62: 6.9926977 | CQ62: 37681 | CR62: =IF(MONTH(CQ62)=MONTH(CQ61),CR61+CP62,CP62) -> 6.9926977 | CT62: 0.42220467 | CU62: 37316 | CV62: =IF(MONTH(CU62)=MONTH(CU61),CV61+CT62,CT62) -> 0.42220467 | CX62: 3.5432949 | CY62: 36951 | CZ62: =IF(MONTH(CY62)=MONTH(CY61),CZ61+CX62,CX62) -> 3.5432949 | DB62: 4.4177847 | DC62: 36586 | DD62: =IF(MONTH(DC62)=MONTH(DC61),DD61+DB62,DB62) -> 4.4177847
A63: =MEDIAN(F63,J63,N63,R63,V63,Z63,AD63,AH63,AL63,AP63,AT63,AX63,BB63,BF63,BJ63,BN63,BR63,BV63,BZ63,CD63,CH63,CL63,CP63,CT63,CX63,DB63) -> 2.420742 | B63: 46814 | C63: =IF(MONTH(B63)=MONTH(B62),A63+C62,A63) -> 4.7026032 | E63: 1097184 | F63: 21.178511 | G63: =E63/24+2 -> 45718 | H63: =IF(MONTH(G63)=MONTH(G62),F63+H62,F63) -> 21.201121 | I63: 1088424 | J63: 5.8020477 | K63: =I63/24+2 -> 45353 | L63: =IF(MONTH(K63)=MONTH(K62),J63+L62,J63) -> 8.7743518 | M63: 1079640 | N63: 2.6318147 | O63: =M63/24+2 -> 44987 | P63: =IF(MONTH(O63)=MONTH(O62),N63+P62,N63) -> 11.757892 | Q63: 1070880 | R63: 31.414825 | S63: =Q63/24+2 -> 44622 | T63: =IF(MONTH(S63)=MONTH(S62),R63+T62,R63) -> 31.958358 | U63: 1062120 | V63: 14.413482 | W63: =U63/24+2 -> 44257 | X63: =IF(MONTH(W63)=MONTH(W62),V63+X62,V63) -> 42.266988 | Y63: 1053360 | Z63: 7.4304175 | AA63: =Y63/24+2 -> 43892 | AB63: =IF(MONTH(AA63)=MONTH(AA62),Z63+AB62,Z63) -> 9.0218357 | AD63: 1.2433081 | AE63: 43526 | AF63: =IF(MONTH(AE63)=MONTH(AE62),AF62+AD63,AD63) -> 1.7098084 | AH63: 27.552505 | AI63: 43161 | AJ63: =IF(MONTH(AI63)=MONTH(AI62),AJ62+AH63,AH63) -> 61.013565 | AL63: 2.2096694 | AM63: 42796 | AN63: =IF(MONTH(AM63)=MONTH(AM62),AN62+AL63,AL63) -> 2.6208378 | AP63: 7.251658 | AQ63: 42431 | AR63: =IF(MONTH(AQ63)=MONTH(AQ62),AR62+AP63,AP63) -> 8.148734 | AT63: 19.729069 | AU63: 42065 | AV63: =IF(MONTH(AU63)=MONTH(AU62),AV62+AT63,AT63) -> 35.73111 | AX63: 3.122622 | AY63: 41700 | AZ63: =IF(MONTH(AY63)=MONTH(AY62),AZ62+AX63,AX63) -> 3.122622 | BB63: 0.20246451 | BC63: 41335 | BD63: =IF(MONTH(BC63)=MONTH(BC62),BD62+BB63,BB63) -> 4.7795524 | BF63: 51.022171 | BG63: 40970 | BH63: =IF(MONTH(BG63)=MONTH(BG62),BH62+BF63,BF63) -> 63.825989 | BJ63: 0 | BK63: 40604 | BL63: =IF(MONTH(BK63)=MONTH(BK62),BL62+BJ63,BJ63) -> 10.302898 | BN63: 14.550858 | BO63: 40239 | BP63: =IF(MONTH(BO63)=MONTH(BO62),BP62+BN63,BN63) -> 15.831612 | BR63: 1.1855253 | BS63: 39874 | BT63: =IF(MONTH(BS63)=MONTH(BS62),BT62+BR63,BR63) -> 5.1866764 | BV63: 1.7458134 | BW63: 39509 | BX63: =IF(MONTH(BW63)=MONTH(BW62),BX62+BV63,BV63) -> 1.7458134 | BZ63: 0 | CA63: 39143 | CB63: =IF(MONTH(CA63)=MONTH(CA62),CB62+BZ63,BZ63) -> 0 | CD63: 0 | CE63: 38778 | CF63: =IF(MONTH(CE63)=MONTH(CE62),CF62+CD63,CD63) -> 0 | CH63: 0.65173179 | CI63: 38413 | CJ63: =IF(MONTH(CI63)=MONTH(CI62),CJ62+CH63,CH63) -> 0.92647606 | CL63: 1.9162766 | CM63: 38048 | CN63: =IF(MONTH(CM63)=MONTH(CM62),CN62+CL63,CL63) -> 8.598786 | CP63: 1.884531 | CQ63: 37682 | CR63: =IF(MONTH(CQ63)=MONTH(CQ62),CR62+CP63,CP63) -> 8.8772287 | CT63: 5.8680353 | CU63: 37317 | CV63: =IF(MONTH(CU63)=MONTH(CU62),CV62+CT63,CT63) -> 6.29024 | CX63: 0.17122641 | CY63: 36952 | CZ63: =IF(MONTH(CY63)=MONTH(CY62),CZ62+CX63,CX63) -> 3.7145213 | DB63: 0.048720054 | DC63: 36587 | DD63: =IF(MONTH(DC63)=MONTH(DC62),DD62+DB63,DB63) -> 4.4665047
A64: =MEDIAN(F64,J64,N64,R64,V64,Z64,AD64,AH64,AL64,AP64,AT64,AX64,BB64,BF64,BJ64,BN64,BR64,BV64,BZ64,CD64,CH64,CL64,CP64,CT64,CX64,DB64) -> 5.4549696 | B64: 46815 | C64: =IF(MONTH(B64)=MONTH(B63),A64+C63,A64) -> 10.157573 | E64: 1097208 | F64: 18.927113 | G64: =E64/24+2 -> 45719 | H64: =IF(MONTH(G64)=MONTH(G63),F64+H63,F64) -> 40.128234 | I64: 1088448 | J64: 6.9670501 | K64: =I64/24+2 -> 45354 | L64: =IF(MONTH(K64)=MONTH(K63),J64+L63,J64) -> 15.741402 | M64: 1079664 | N64: 7.0860991 | O64: =M64/24+2 -> 44988 | P64: =IF(MONTH(O64)=MONTH(O63),N64+P63,N64) -> 18.843992 | Q64: 1070904 | R64: 10.189713 | S64: =Q64/24+2 -> 44623 | T64: =IF(MONTH(S64)=MONTH(S63),R64+T63,R64) -> 42.14807 | U64: 1062144 | V64: 24.382816 | W64: =U64/24+2 -> 44258 | X64: =IF(MONTH(W64)=MONTH(W63),V64+X63,V64) -> 66.649804 | Y64: 1053384 | Z64: 1.1279926 | AA64: =Y64/24+2 -> 43893 | AB64: =IF(MONTH(AA64)=MONTH(AA63),Z64+AB63,Z64) -> 10.149828 | AD64: 5.4585438 | AE64: 43527 | AF64: =IF(MONTH(AE64)=MONTH(AE63),AF63+AD64,AD64) -> 7.1683522 | AH64: 6.3288689 | AI64: 43162 | AJ64: =IF(MONTH(AI64)=MONTH(AI63),AJ63+AH64,AH64) -> 67.342434 | AL64: 0.73604387 | AM64: 42797 | AN64: =IF(MONTH(AM64)=MONTH(AM63),AN63+AL64,AL64) -> 3.3568816 | AP64: 5.4513955 | AQ64: 42432 | AR64: =IF(MONTH(AQ64)=MONTH(AQ63),AR63+AP64,AP64) -> 13.60013 | AT64: 2.3233359 | AU64: 42066 | AV64: =IF(MONTH(AU64)=MONTH(AU63),AV63+AT64,AT64) -> 38.054446 | AX64: 26.464182 | AY64: 41701 | AZ64: =IF(MONTH(AY64)=MONTH(AY63),AZ63+AX64,AX64) -> 29.586804 | BB64: 5.4680967 | BC64: 41336 | BD64: =IF(MONTH(BC64)=MONTH(BC63),BD63+BB64,BB64) -> 10.247649 | BF64: 32.557522 | BG64: 40971 | BH64: =IF(MONTH(BG64)=MONTH(BG63),BH63+BF64,BF64) -> 96.383511 | BJ64: 1.2332761 | BK64: 40605 | BL64: =IF(MONTH(BK64)=MONTH(BK63),BL63+BJ64,BJ64) -> 11.536175 | BN64: 11.071673 | BO64: 40240 | BP64: =IF(MONTH(BO64)=MONTH(BO63),BP63+BN64,BN64) -> 26.903285 | BR64: 32.941059 | BS64: 39875 | BT64: =IF(MONTH(BS64)=MONTH(BS63),BT63+BR64,BR64) -> 38.127735 | BV64: 0 | BW64: 39510 | BX64: =IF(MONTH(BW64)=MONTH(BW63),BX63+BV64,BV64) -> 1.7458134 | BZ64: 0 | CA64: 39144 | CB64: =IF(MONTH(CA64)=MONTH(CA63),CB63+BZ64,BZ64) -> 0 | CD64: 0 | CE64: 38779 | CF64: =IF(MONTH(CE64)=MONTH(CE63),CF63+CD64,CD64) -> 0 | CH64: 11.172143 | CI64: 38414 | CJ64: =IF(MONTH(CI64)=MONTH(CI63),CJ63+CH64,CH64) -> 12.098619 | CL64: 3.1189523 | CM64: 38049 | CN64: =IF(MONTH(CM64)=MONTH(CM63),CN63+CL64,CL64) -> 11.717738 | CP64: 3.1761134 | CQ64: 37683 | CR64: =IF(MONTH(CQ64)=MONTH(CQ63),CR63+CP64,CP64) -> 12.053342 | CT64: 0.16403233 | CU64: 37318 | CV64: =IF(MONTH(CU64)=MONTH(CU63),CV63+CT64,CT64) -> 6.4542723 | CX64: 2.5971322 | CY64: 36953 | CZ64: =IF(MONTH(CY64)=MONTH(CY63),CZ63+CX64,CX64) -> 6.3116535 | DB64: 2.600071 | DC64: 36588 | DD64: =IF(MONTH(DC64)=MONTH(DC63),DD63+DB64,DB64) -> 7.0665757
A65: =MEDIAN(F65,J65,N65,R65,V65,Z65,AD65,AH65,AL65,AP65,AT65,AX65,BB65,BF65,BJ65,BN65,BR65,BV65,BZ65,CD65,CH65,CL65,CP65,CT65,CX65,DB65) -> 3.3404515 | B65: 46816 | C65: =IF(MONTH(B65)=MONTH(B64),A65+C64,A65) -> 13.498024 | E65: 1097232 | F65: 1.8646449 | G65: =E65/24+2 -> 45720 | H65: =IF(MONTH(G65)=MONTH(G64),F65+H64,F65) -> 41.992879 | I65: 1088472 | J65: 2.2645531 | K65: =I65/24+2 -> 45355 | L65: =IF(MONTH(K65)=MONTH(K64),J65+L64,J65) -> 18.005955 | M65: 1079688 | N65: 22.548365 | O65: =M65/24+2 -> 44989 | P65: =IF(MONTH(O65)=MONTH(O64),N65+P64,N65) -> 41.392356 | Q65: 1070928 | R65: 3.21825 | S65: =Q65/24+2 -> 44624 | T65: =IF(MONTH(S65)=MONTH(S64),R65+T64,R65) -> 45.36632 | U65: 1062168 | V65: 8.5946655 | W65: =U65/24+2 -> 44259 | X65: =IF(MONTH(W65)=MONTH(W64),V65+X64,V65) -> 75.24447 | Y65: 1053408 | Z65: 0.86818981 | AA65: =Y65/24+2 -> 43894 | AB65: =IF(MONTH(AA65)=MONTH(AA64),Z65+AB64,Z65) -> 11.018018 | AD65: 0.38082778 | AE65: 43528 | AF65: =IF(MONTH(AE65)=MONTH(AE64),AF64+AD65,AD65) -> 7.54918 | AH65: 0.5092563 | AI65: 43163 | AJ65: =IF(MONTH(AI65)=MONTH(AI64),AJ64+AH65,AH65) -> 67.85169 | AL65: 2.7461679 | AM65: 42798 | AN65: =IF(MONTH(AM65)=MONTH(AM64),AN64+AL65,AL65) -> 6.1030495 | AP65: 6.2164741 | AQ65: 42433 | AR65: =IF(MONTH(AQ65)=MONTH(AQ64),AR64+AP65,AP65) -> 19.816604 | AT65: 2.5363269 | AU65: 42067 | AV65: =IF(MONTH(AU65)=MONTH(AU64),AV64+AT65,AT65) -> 40.590772 | AX65: 3.4626529 | AY65: 41702 | AZ65: =IF(MONTH(AY65)=MONTH(AY64),AZ64+AX65,AX65) -> 33.049457 | BB65: 2.1569219 | BC65: 41337 | BD65: =IF(MONTH(BC65)=MONTH(BC64),BD64+BB65,BB65) -> 12.404571 | BF65: 27.156269 | BG65: 40972 | BH65: =IF(MONTH(BG65)=MONTH(BG64),BH64+BF65,BF65) -> 123.53978 | BJ65: 8.6860991 | BK65: 40606 | BL65: =IF(MONTH(BK65)=MONTH(BK64),BL64+BJ65,BJ65) -> 20.222274 | BN65: 0 | BO65: 40241 | BP65: =IF(MONTH(BO65)=MONTH(BO64),BP64+BN65,BN65) -> 26.903285 | BR65: 13.310629 | BS65: 39876 | BT65: =IF(MONTH(BS65)=MONTH(BS64),BT64+BR65,BR65) -> 51.438364 | BV65: 1.6616962 | BW65: 39511 | BX65: =IF(MONTH(BW65)=MONTH(BW64),BX64+BV65,BV65) -> 3.4075096 | BZ65: 3.6989512 | CA65: 39145 | CB65: =IF(MONTH(CA65)=MONTH(CA64),CB64+BZ65,BZ65) -> 3.6989512 | CD65: 0 | CE65: 38780 | CF65: =IF(MONTH(CE65)=MONTH(CE64),CF64+CD65,CD65) -> 0 | CH65: 0 | CI65: 38415 | CJ65: =IF(MONTH(CI65)=MONTH(CI64),CJ64+CH65,CH65) -> 12.098619 | CL65: 14.918016 | CM65: 38050 | CN65: =IF(MONTH(CM65)=MONTH(CM64),CN64+CL65,CL65) -> 26.635755 | CP65: 14.454524 | CQ65: 37684 | CR65: =IF(MONTH(CQ65)=MONTH(CQ64),CR64+CP65,CP65) -> 26.507866 | CT65: 19.412468 | CU65: 37319 | CV65: =IF(MONTH(CU65)=MONTH(CU64),CV64+CT65,CT65) -> 25.86674 | CX65: 4.7422628 | CY65: 36954 | CZ65: =IF(MONTH(CY65)=MONTH(CY64),CZ64+CX65,CX65) -> 11.053916 | DB65: 5.000402 | DC65: 36589 | DD65: =IF(MONTH(DC65)=MONTH(DC64),DD64+DB65,DB65) -> 12.066978
